Workbook

Sheet Dashboard
A1: Gulf Startup & University Advisor Outreach Database – Madhiyazhagan
A2: UAE (Dubai focus) • Saudi Arabia • Oman • Kuwait • Bahrain | Curated for external advisor / mentor outreach | 26 Sep 2026
A4: Database KPI | B4: Value | D4: Outreach Readiness | E4: Value
A5: Total targets | B5: =COUNTA('Master Mail List'!A2:A66) -> 65 | D5: Named contact + email | E5: =COUNTIF('Master Mail List'!U2:U66,"Named contact + public email") -> 17
A6: Countries | B6: 5 | D6: Functional / program email | E6: =COUNTIF('Master Mail List'!U2:U66,"Functional / program email") -> 37
A7: Primary-email targets | B7: =COUNTA('Master Mail List'!K2:K66) -> 54 | D7: Official route – no email | E7: =COUNTIF('Master Mail List'!U2:U66,"Official route – no public email verified") -> 11
A8: Priority A | B8: =COUNTIF('Master Mail List'!P2:P66,"A") -> 45 | D8: Drafted | E8: =COUNTIF('Master Mail List'!W2:W66,"Drafted") -> 0
A9: Engineering / Tech Universities | B9: =COUNTIF('Master Mail List'!E2:E66,"Engineering / Technology University") -> 15 | D9: Sent | E9: =COUNTIF('Master Mail List'!W2:W66,"Sent") -> 32
A10: B-School / University Entrepreneurship | B10: =COUNTIF('Master Mail List'!E2:E66,"B-School / University Entrepreneurship") -> 14 | D10: Meetings | E10: =COUNTIF('Master Mail List'!W2:W66,"Meeting Booked") -> 0
A11: Accelerators / Incubators | B11: =COUNTIF('Master Mail List'!E2:E66,"Accelerator / Incubator") -> 21
A12: Government / Startup Ecosystem | B12: =COUNTIF('Master Mail List'!E2:E66,"Government / Startup Ecosystem") -> 15
A15: Country | B15: Targets | D15: Country | E15: Total | F15: With Email
A16: UAE | B16: =COUNTIF('Master Mail List'!B2:B66,A16) -> 19 | D16: UAE | E16: =COUNTIF('Master Mail List'!B2:B66,D16) -> 19 | F16: =COUNTIFS('Master Mail List'!B2:B66,D16,'Master Mail List'!K2:K66,"<>") -> 15
A17: Saudi Arabia | B17: =COUNTIF('Master Mail List'!B2:B66,A17) -> 16 | D17: Saudi Arabia | E17: =COUNTIF('Master Mail List'!B2:B66,D17) -> 16 | F17: =COUNTIFS('Master Mail List'!B2:B66,D17,'Master Mail List'!K2:K66,"<>") -> 13
A18: Oman | B18: =COUNTIF('Master Mail List'!B2:B66,A18) -> 11 | D18: Oman | E18: =COUNTIF('Master Mail List'!B2:B66,D18) -> 11 | F18: =COUNTIFS('Master Mail List'!B2:B66,D18,'Master Mail List'!K2:K66,"<>") -> 11
A19: Kuwait | B19: =COUNTIF('Master Mail List'!B2:B66,A19) -> 8 | D19: Kuwait | E19: =COUNTIF('Master Mail List'!B2:B66,D19) -> 8 | F19: =COUNTIFS('Master Mail List'!B2:B66,D19,'Master Mail List'!K2:K66,"<>") -> 7
A20: Bahrain | B20: =COUNTIF('Master Mail List'!B2:B66,A20) -> 11 | D20: Bahrain | E20: =COUNTIF('Master Mail List'!B2:B66,D20) -> 11 | F20: =COUNTIFS('Master Mail List'!B2:B66,D20,'Master Mail List'!K2:K66,"<>") -> 8

Sheet Master Mail List
A1: ID | B1: Country | C1: Region / Emirate / Province | D1: City | E1: Category | F1: Institution / Organisation | G1: Incubator / Program / Unit | H1: Organisation Profile / Relevance | I1: Contact Name | J1: Contact Role | K1: Primary Email | L1: CC / Alternate Email | M1: Phone | N1: Contact / Profile URL | O1: Official Source URL | P1: Priority | Q1: Why Madhiyazhagan Fits | R1: Suggested Subject | S1: Personalization Hook | T1: Best Entry Route | U1: Contact Quality | V1: Verified On | W1: Email Status | X1: Last Contacted | Y1: Notes
A2: 1 | B2: UAE | C2: Abu Dhabi | D2: Abu Dhabi | E2: Accelerator / Incubator | F2: Hub71 | G2: Hub71 startup ecosystem | H2: Abu Dhabi global tech ecosystem offering startup programs, market access, investor and corporate connections. | I2: Hub71 Team | J2: Ecosystem / startup team | K2: info@hub71.com | M2: +971 2 449 1515 | N2: https://www.hub71.com/ | O2: https://www.hub71.com/contact | P2: A | Q2: Cohort mentoring, AI/product strategy, enterprise GTM, founder reviews and Germany/Europe–GCC market access. | R2: External Advisor / Mentor – AI, Product & Germany–GCC | Hub71 startup ecosystem | S2: I came across Hub71 startup ecosystem at Hub71 and its work around abu dhabi global tech ecosystem offering startup programs, market access, investor and corporate connections. | T2: Use the program/functional email with a concise external mentor/advisor proposition. | U2: Functional / program email | V2: 46291 | W2: Already contacted | Y2: Already emailed in earlier batch (same address)
A3: 2 | B3: UAE | C3: Abu Dhabi | D3: Abu Dhabi | E3: Accelerator / Incubator | F3: startAD – NYU Abu Dhabi | G3: startAD | H3: NYU Abu Dhabi-based accelerator and innovation platform connecting startups, corporates, investors and mentors. | I3: Ashwin Joshi | J3: Director, startAD | K3: startAD@nyu.edu | N3: https://startad.ae/ | O3: https://startad.ae/contact/ | P3: A | Q3: Cohort mentoring, AI/product strategy, enterprise GTM, founder reviews and Germany/Europe–GCC market access. | R3: External Advisor / Mentor – AI, Product & Germany–GCC | startAD | S3: I came across startAD at startAD – NYU Abu Dhabi and its work around nyu abu dhabi-based accelerator and innovation platform connecting startups, corporates, investors and mentors. | T3: Write directly to the named contact using the public email and ask about contributing to the mentor/advisor network. | U3: Named contact + public email | V3: 46291 | W3: Already contacted | Y3: Already emailed in earlier batch (same address)
A4: 3 | B4: UAE | C4: Dubai | D4: Dubai | E4: Accelerator / Incubator | F4: Dubai Technology Entrepreneur Campus (Dtec) | G4: Dtec | H4: Dubai Silicon Oasis technology startup hub offering incubation, workspace, market access and ecosystem support. | I4: Dtec Team | J4: Startup / ecosystem team | K4: dtec.sales@dtec.ae | L4: community@dtec.ae | M4: +971 4 501 5000 | N4: https://dtec.ae/ | O4: https://dtec.ae/contact/ | P4: A | Q4: Cohort mentoring, AI/product strategy, enterprise GTM, founder reviews and Germany/Europe–GCC market access. | R4: External Advisor / Mentor – AI, Product & Germany–GCC | Dtec | S4: I came across Dtec at Dubai Technology Entrepreneur Campus (Dtec) and its work around dubai silicon oasis technology startup hub offering incubation, workspace, market access and ecosystem support. | T4: Use the program/functional email with a concise external mentor/advisor proposition. | U4: Functional / program email | V4: 46291 | W4: Skipped | Y4: Dtec already emailed (dtec@dso.ae)
A5: 4 | B5: UAE | C5: Dubai | D5: Dubai | E5: Government / Startup Ecosystem | F5: Mohammed Bin Rashid Innovation Fund (MBRIF) | G5: Innovation Accelerator | H5: UAE Ministry of Finance initiative supporting innovative companies through acceleration and growth services. | I5: MBRIF Team | J5: Innovation / accelerator team | K5: contact@mbrif.ae | L5: info@mbrinnovationfund.ae | N5: https://mbrif.ae/ | O5: https://mbrif.ae/ar/contact-us-2/ | P5: A | Q5: Founder capacity building, AI adoption, mentor programs, ecosystem partnerships and Germany/Europe–GCC market connections. | R5: External Mentor / Advisor Support | Innovation Accelerator | S5: I came across Innovation Accelerator at Mohammed Bin Rashid Innovation Fund (MBRIF) and its work around uae ministry of finance initiative supporting innovative companies through acceleration and growth services. | T5: Use the program/functional email with a concise external mentor/advisor proposition. | U5: Functional / program email | V5: 46291 | W5: Sent | X5: 46291 | Y5: Position around founder mentoring, enterprise readiness and international expansion.
A6: 5 | B6: UAE | C6: Sharjah | D6: Sharjah | E6: Accelerator / Incubator | F6: Sharjah Entrepreneurship Center (Sheraa) | G6: Sheraa | H6: Sharjah startup ecosystem builder supporting founders through programs, incubation, mentorship and market access. | I6: Sara Abdelaziz Al Nuaimi | J6: CEO | K6: info@sheraa.ae | M6: +971 6 558 5000 | N6: https://sheraa.ae/about-us | O6: https://sheraa.ae/contact-us | P6: A | Q6: Cohort mentoring, AI/product strategy, enterprise GTM, founder reviews and Germany/Europe–GCC market access. | R6: External Advisor / Mentor – AI, Product & Germany–GCC | Sheraa | S6: I came across Sheraa at Sharjah Entrepreneurship Center (Sheraa) and its work around sharjah startup ecosystem builder supporting founders through programs, incubation, mentorship and market access. | T6: Write directly to the named contact using the public email and ask about contributing to the mentor/advisor network. | U6: Named contact + public email | V6: 46291 | W6: Already contacted | Y6: Already emailed in earlier batch (same address)
A7: 6 | B7: UAE | C7: Dubai | D7: Dubai | E7: Accelerator / Incubator | F7: DIFC Innovation Hub | G7: Innovation Hub | H7: Dubai International Financial Centre innovation ecosystem for fintech, AI, digital assets and venture growth. | I7: Mohammad Alblooshi | J7: Chief Executive Officer | N7: https://www.innovationhub.difc.ae/the-hub/about-innovation-hub | O7: https://www.innovationhub.difc.ae/ | P7: B | Q7: Cohort mentoring, AI/product strategy, enterprise GTM, founder reviews and Germany/Europe–GCC market access. | R7: External Advisor / Mentor – AI, Product & Germany–GCC | Innovation Hub | S7: I came across Innovation Hub at DIFC Innovation Hub and its work around dubai international financial centre innovation ecosystem for fintech, ai, digital assets and venture growth. | T7: Use the official contact/partnership route and ask to be connected to the mentor, partnerships or incubation lead. | U7: Official route – no public email verified | V7: 46291 | W7: Skipped | Y7: No email in database
A8: 7 | B8: UAE | C8: Dubai | D8: Dubai | E8: Government / Startup Ecosystem | F8: Dubai Future Foundation | G8: Future ecosystem / innovation programs | H8: Dubai government innovation platform running future technology, startup and ecosystem initiatives. | I8: Dubai Future Foundation Team | J8: Partnership / innovation team | M8: +971 4 516 6565 | N8: https://www.dubaifuture.ae/ | O8: https://www.dubaifuture.ae/reach-us/ | P8: B | Q8: Founder capacity building, AI adoption, mentor programs, ecosystem partnerships and Germany/Europe–GCC market connections. | R8: External Mentor / Advisor Support | Future ecosystem / innovation programs | S8: I came across Future ecosystem / innovation programs at Dubai Future Foundation and its work around dubai government innovation platform running future technology, startup and ecosystem initiatives. | T8: Use the official contact/partnership route and ask to be connected to the mentor, partnerships or incubation lead. | U8: Official route – no public email verified | V8: 46291 | W8: Skipped | Y8: No email in database
A9: 8 | B9: UAE | C9: Dubai | D9: Dubai | E9: Government / Startup Ecosystem | F9: Dubai Chamber of Digital Economy | G9: Digital Economy ecosystem | H9: Dubai Chambers entity supporting digital companies, startups, market entry and ecosystem development. | I9: Digital Economy Team | J9: Customer / ecosystem team | K9: customercare@dubaichamber.com | M9: 800 CHAMBER (242 6237) | N9: https://www.dubaichamber.com/ | O9: https://myhub.dubaichamber.com/en/web/dubai-chamber-of-digital-economy/home | P9: A | Q9: Founder capacity building, AI adoption, mentor programs, ecosystem partnerships and Germany/Europe–GCC market connections. | R9: External Mentor / Advisor Support | Digital Economy ecosystem | S9: I came across Digital Economy ecosystem at Dubai Chamber of Digital Economy and its work around dubai chambers entity supporting digital companies, startups, market entry and ecosystem development. | T9: Use the program/functional email with a concise external mentor/advisor proposition. | U9: Functional / program email | V9: 46291 | W9: Skipped | Y9: Only a customer care inbox
A10: 9 | B10: UAE | C10: Abu Dhabi | D10: Abu Dhabi | E10: Government / Startup Ecosystem | F10: Khalifa Fund for Enterprise Development | G10: Entrepreneurship support | H10: Abu Dhabi government entity supporting entrepreneurship, SME development, capability building and market access. | I10: Khalifa Fund Team | J10: Entrepreneurship support team | K10: info@khalifafund.ae | M10: +971 2 696 0000 | N10: https://www.khalifafund.ae/ | O10: https://www.khalifafund.ae/contact/ | P10: A | Q10: Founder capacity building, AI adoption, mentor programs, ecosystem partnerships and Germany/Europe–GCC market connections. | R10: External Mentor / Advisor Support | Entrepreneurship support | S10: I came across Entrepreneurship support at Khalifa Fund for Enterprise Development and its work around abu dhabi government entity supporting entrepreneurship, sme development, capability building and market access. | T10: Use the program/functional email with a concise external mentor/advisor proposition. | U10: Functional / program email | V10: 46291 | W10: Sent | X10: 46291 | Y10: Offer founder mentoring, AI adoption and Germany/Europe connections.
A11: 10 | B11: UAE | C11: Sharjah | D11: Sharjah | E11: Government / Startup Ecosystem | F11: Sharjah SME – RUWAD | G11: Entrepreneurship support | H11: Sharjah government SME development body supporting entrepreneurs through advisory, training and business support. | I11: RUWAD Team | J11: SME / entrepreneurship team | K11: info@ruwad.ae | L11: cs@ruwad.ae | M11: +971 6 512 2555 | N11: https://www.ruwad.ae/ | O11: https://www.ruwad.ae/ | P11: A | Q11: Founder capacity building, AI adoption, mentor programs, ecosystem partnerships and Germany/Europe–GCC market connections. | R11: External Mentor / Advisor Support | Entrepreneurship support | S11: I came across Entrepreneurship support at Sharjah SME – RUWAD and its work around sharjah government sme development body supporting entrepreneurs through advisory, training and business support. | T11: Use the program/functional email with a concise external mentor/advisor proposition. | U11: Functional / program email | V11: 46291 | W11: Sent | X11: 46291 | Y11: Good route for mentor/advisor contribution to SME founders.
A12: 11 | B12: UAE | C12: Dubai | D12: Dubai | E12: B-School / University Entrepreneurship | F12: University of Dubai | G12: Innovation, Entrepreneurship & Business Centre (IEBC) | H12: University entrepreneurship centre offering pitch competitions, workshops, mentoring, incubation and ecosystem connections. | I12: IEBC Team | J12: Entrepreneurship & incubation team | K12: Info.iebc@ud.ac.ae | L12: startup.support@ud.ac.ae | M12: +971 4 556 6800 | N12: https://ud.ac.ae/entrepreneurship-and-business-centre-udiebc/ | O12: https://ud.ac.ae/entrepreneurship-and-business-centre-udiebc/ | P12: A | Q12: Startup mentoring, business models, GTM, enterprise readiness, entrepreneurship education and Germany–GCC connections. | R12: External Advisor / Mentor – AI, Product & Germany–GCC | University of Dubai | S12: I came across Innovation, Entrepreneurship & Business Centre (IEBC) at University of Dubai and its work around university entrepreneurship centre offering pitch competitions, workshops, mentoring, incubation and ecosystem connections. | T12: Use the program/functional email with a concise external mentor/advisor proposition. | U12: Functional / program email | V12: 46291 | W12: Already contacted | Y12: Already emailed in earlier batch (same address)
A13: 12 | B13: UAE | C13: Abu Dhabi | D13: Abu Dhabi | E13: Engineering / Technology University | F13: Khalifa University | G13: Technology Management & Innovation | H13: University office responsible for research commercialization, startups, licensing and industry engagement. | I13: Aysha Ali Rashed AlNuaimi | J13: Acting Director, Technology Management & Innovation | K13: aysha.alnuaimi@ku.ac.ae | L13: ip@ku.ac.ae | N13: https://www.ku.ac.ae/research-offices/technology-management-innovation/our-team | O13: https://www.ku.ac.ae/research-offices/technology-management-innovation | P13: A | Q13: AI/product strategy, enterprise technology, research commercialization, founder mentoring and Germany–GCC market connections. | R13: External Advisor / Mentor – AI, Product & Germany–GCC | Technology Management & Innovation | S13: I came across Technology Management & Innovation at Khalifa University and its work around university office responsible for research commercialization, startups, licensing and industry engagement. | T13: Write directly to the named contact using the public email and ask about contributing to the mentor/advisor network. | U13: Named contact + public email | V13: 46291 | W13: Sent | X13: 46291 | Y13: Direct named decision-maker and strong commercialization fit.
A14: 13 | B14: UAE | C14: Abu Dhabi | D14: Abu Dhabi | E14: Engineering / Technology University | F14: Mohamed bin Zayed University of Artificial Intelligence (MBZUAI) | G14: Incubation & Entrepreneurship Center (IEC) | H14: AI university incubation center helping founders build and scale AI startups, with mentor and ecosystem partner networks. | I14: IEC Team | J14: Incubation & Entrepreneurship Center | K14: iec@mbzuai.ac.ae | L14: info@mbzuai.ac.ae | M14: +971 2 811 3333 | N14: https://mbzuai.ac.ae/innovation-partnerships/incubation-entrepreneurship-center | O14: https://mbzuai.ac.ae/about-us/contact-mbzuai | P14: A | Q14: AI/product strategy, enterprise technology, research commercialization, founder mentoring and Germany–GCC market connections. | R14: External Advisor / Mentor – AI, Product & Germany–GCC | Mohamed bin Zayed University of Artificial Intelligence (MBZUAI) | S14: I came across Incubation & Entrepreneurship Center (IEC) at Mohamed bin Zayed University of Artificial Intelligence (MBZUAI) and its work around ai university incubation center helping founders build and scale ai startups, with mentor and ecosystem partner networks. | T14: Use the program/functional email with a concise external mentor/advisor proposition. | U14: Functional / program email | V14: 46291 | W14: Sent | X14: 46291 | Y14: Very strong AI/startup mentoring alignment.
A15: 14 | B15: UAE | C15: Sharjah | D15: Sharjah | E15: Engineering / Technology University | F15: University of Sharjah | G15: Innovation Hub | H15: University innovation hub supporting entrepreneurship, technology development and commercialization. | I15: Engr. Mahmoud Abu Shammeh | J15: Director, Innovation Hub | K15: abushammeh@sharjah.ac.ae | L15: mmadi@sharjah.ac.ae | N15: https://www.sharjah.ac.ae/en/Services/Departments/Innovation-Hub | O15: https://www.sharjah.ac.ae/en/Services/Departments/Innovation-Hub | P15: A | Q15: AI/product strategy, enterprise technology, research commercialization, founder mentoring and Germany–GCC market connections. | R15: External Advisor / Mentor – AI, Product & Germany–GCC | Innovation Hub | S15: I came across Innovation Hub at University of Sharjah and its work around university innovation hub supporting entrepreneurship, technology development and commercialization. | T15: Write directly to the named contact using the public email and ask about contributing to the mentor/advisor network. | U15: Named contact + public email | V15: 46291 | W15: Sent | X15: 46291 | Y15: Named director; strong innovation/commercialization target.
A16: 15 | B16: UAE | C16: Abu Dhabi | D16: Al Ain | E16: B-School / University Entrepreneurship | F16: United Arab Emirates University (UAEU) | G16: Emirates Centre for Entrepreneurship Research | H16: University entrepreneurship research ecosystem linking entrepreneurship, education, research and enterprise development. | I16: Dr. Ishara Maharaj | J16: Entrepreneurship research contact | K16: ishara.maharaj@uaeu.ac.ae | L16: savagepd@uaeu.ac.ae | N16: https://www.uaeu.ac.ae/en/research/ | O16: https://www.uaeu.ac.ae/en/research/research-booklet-uaeu-2024.pdf | P16: B | Q16: Startup mentoring, business models, GTM, enterprise readiness, entrepreneurship education and Germany–GCC connections. | R16: External Advisor / Mentor – AI, Product & Germany–GCC | United Arab Emirates University (UAEU) | S16: I came across Emirates Centre for Entrepreneurship Research at United Arab Emirates University (UAEU) and its work around university entrepreneurship research ecosystem linking entrepreneurship, education, research and enterprise development. | T16: Write directly to the named contact using the public email and ask about contributing to the mentor/advisor network. | U16: Named contact + public email | V16: 46291 | W16: Sent | X16: 46291 | Y16: Good for entrepreneurship teaching, research and mentor collaboration.
A17: 16 | B17: UAE | C17: Dubai | D17: Dubai | E17: Engineering / Technology University | F17: Rochester Institute of Technology Dubai (RIT Dubai) | G17: Projects & Development / entrepreneurship ecosystem | H17: Technology-focused Dubai campus with industry projects and entrepreneurship-oriented activities. | I17: Yousef Al Mannaee | J17: Projects & Development Manager | K17: yaacad@rit.edu | L17: dubai@rit.edu | M17: +971 4 371 2000 | N17: https://www.rit.edu/dubai/directory | O17: https://www.rit.edu/dubai/ | P17: A | Q17: AI/product strategy, enterprise technology, research commercialization, founder mentoring and Germany–GCC market connections. | R17: External Advisor / Mentor – AI, Product & Germany–GCC | Rochester Institute of Technology Dubai (RIT Dubai) | S17: I came across Projects & Development / entrepreneurship ecosystem at Rochester Institute of Technology Dubai (RIT Dubai) and its work around technology-focused dubai campus with industry projects and entrepreneurship-oriented activities. | T17: Write directly to the named contact using the public email and ask about contributing to the mentor/advisor network. | U17: Named contact + public email | V17: 46291 | W17: Sent | X17: 46291 | Y17: Direct contact plus technology and industry-project fit.
A18: 17 | B18: UAE | C18: Dubai | D18: Dubai | E18: B-School / University Entrepreneurship | F18: SP Jain School of Global Management | G18: Dubai Campus | H18: Global business school with Dubai campus and entrepreneurship/business programs. | I18: Amol Sawant | J18: Dubai campus contact | K18: amol.sawant@spjain.org | L18: admissions.dxb@spjain.org | N18: https://www.spjain.org/global-campus/dubai | O18: https://www.spjain.ae/contact-us | P18: B | Q18: Startup mentoring, business models, GTM, enterprise readiness, entrepreneurship education and Germany–GCC connections. | R18: External Advisor / Mentor – AI, Product & Germany–GCC | Dubai Campus | S18: I came across Dubai Campus at SP Jain School of Global Management and its work around global business school with dubai campus and entrepreneurship/business programs. | T18: Write directly to the named contact using the public email and ask about contributing to the mentor/advisor network. | U18: Named contact + public email | V18: 46291 | W18: Sent | X18: 46291 | Y18: Pitch mentor/guest advisor role around AI, product, startup execution and Europe connections.
A19: 18 | B19: UAE | C19: Dubai / Abu Dhabi | D19: Dubai | E19: B-School / University Entrepreneurship | F19: Zayed University | G19: Innovation & Entrepreneurship Center | H19: University center supporting innovation, entrepreneurship education and engagement with ecosystem partners. | I19: Innovation & Entrepreneurship Center Team | J19: University entrepreneurship team | N19: https://www.zu.ac.ae/main/en/ie-center/index | O19: https://www.zu.ac.ae/main/en/ie-center/index | P19: B | Q19: Startup mentoring, business models, GTM, enterprise readiness, entrepreneurship education and Germany–GCC connections. | R19: External Advisor / Mentor – AI, Product & Germany–GCC | Innovation & Entrepreneurship Center | S19: I came across Innovation & Entrepreneurship Center at Zayed University and its work around university center supporting innovation, entrepreneurship education and engagement with ecosystem partners. | T19: Use the official contact/partnership route and ask to be connected to the mentor, partnerships or incubation lead. | U19: Official route – no public email verified | V19: 46291 | W19: Skipped | Y19: No email in database
A20: 19 | B20: UAE | C20: Sharjah | D20: Sharjah | E20: B-School / University Entrepreneurship | F20: American University of Sharjah | G20: Department of Management, Strategy & Entrepreneurship | H20: Business-school department covering entrepreneurship, strategy and management with industry-facing academic activity. | I20: Dr. Virginia Bodolica | J20: Department leadership | N20: https://www.aus.edu/sba/department-of-management-strategy-entrepreneurship | O20: https://www.aus.edu/sba/department-of-management-strategy-entrepreneurship | P20: C | Q20: Startup mentoring, business models, GTM, enterprise readiness, entrepreneurship education and Germany–GCC connections. | R20: External Advisor / Mentor – AI, Product & Germany–GCC | American University of Sharjah | S20: I came across Department of Management, Strategy & Entrepreneurship at American University of Sharjah and its work around business-school department covering entrepreneurship, strategy and management with industry-facing academic activity. | T20: Use the official contact/partnership route and ask to be connected to the mentor, partnerships or incubation lead. | U20: Official route – no public email verified | V20: 46291 | W20: Skipped | Y20: No email in database
A21: 20 | B21: Saudi Arabia | C21: Riyadh | D21: Riyadh | E21: Government / Startup Ecosystem | F21: Monsha'at – Small and Medium Enterprises General Authority | G21: Innovation Center | H21: Saudi government innovation centers supporting technology startups through incubation, consultations, workshops and expert guidance. | I21: Monsha'at Innovation Center Team | J21: Innovation Center | K21: InnovationCenters@monshaat.gov.sa | L21: Info@monshaat.gov.sa | M21: 8003018888 | N21: https://www.monshaat.gov.sa/en/innovation_center | O21: https://www.monshaat.gov.sa/en/support | P21: A | Q21: Founder capacity building, AI adoption, mentor programs, ecosystem partnerships and Germany/Europe–GCC market connections. | R21: External Mentor / Advisor Support | Innovation Center | S21: I came across Innovation Center at Monsha'at – Small and Medium Enterprises General Authority and its work around saudi government innovation centers supporting technology startups through incubation, consultations, workshops and expert guidance. | T21: Use the program/functional email with a concise external mentor/advisor proposition. | U21: Functional / program email | V21: 46291 | W21: Sent | X21: 46291 | Y21: Explicit expert consultations make this a strong external-mentor target.
A22: 21 | B22: Saudi Arabia | C22: Riyadh | D22: Riyadh | E22: Government / Startup Ecosystem | F22: Ministry of Communications and Information Technology (MCIT) | G22: CODE Gate | H22: Government technology entrepreneurship platform supporting digital startups and innovation programs. | I22: CODE / MCIT Team | J22: Technology entrepreneurship team | K22: info@mcit.gov.sa | M22: 011 814 4444 | N22: https://code.mcit.gov.sa/ | O22: https://my.gov.sa/en/services/2477063 | P22: A | Q22: Founder capacity building, AI adoption, mentor programs, ecosystem partnerships and Germany/Europe–GCC market connections. | R22: External Mentor / Advisor Support | CODE Gate | S22: I came across CODE Gate at Ministry of Communications and Information Technology (MCIT) and its work around government technology entrepreneurship platform supporting digital startups and innovation programs. | T22: Use the program/functional email with a concise external mentor/advisor proposition. | U22: Functional / program email | V22: 46291 | W22: Skipped | Y22: Only a general ministry inbox
A23: 22 | B23: Saudi Arabia | C23: Riyadh | D23: Riyadh | E23: Government / Startup Ecosystem | F23: Ministry of Communications and Information Technology (MCIT) | G23: Tech Founders | H23: MCIT technology entrepreneurship program supporting startup founders and technology venture development. | I23: Tech Founders Team | J23: Technology entrepreneurship program | K23: info@mcit.gov.sa | M23: 011 814 4444 | N23: https://www.mcit.gov.sa/ | O23: https://my.gov.sa/en/services/2422923 | P23: B | Q23: Founder capacity building, AI adoption, mentor programs, ecosystem partnerships and Germany/Europe–GCC market connections. | R23: External Mentor / Advisor Support | Tech Founders | S23: I came across Tech Founders at Ministry of Communications and Information Technology (MCIT) and its work around mcit technology entrepreneurship program supporting startup founders and technology venture development. | T23: Use the program/functional email with a concise external mentor/advisor proposition. | U23: Functional / program email | V23: 46291 | W23: Skipped | Y23: Only a general ministry inbox
A24: 23 | B24: Saudi Arabia | C24: Riyadh | D24: Riyadh | E24: Accelerator / Incubator | F24: Mohammed bin Salman Foundation (Misk) | G24: Misk Entrepreneurship | H24: Entrepreneurship programs supporting young founders, venture development and ecosystem connections. | I24: Misk Entrepreneurship Team | J24: Entrepreneurship team | K24: contact@misk.org.sa | N24: https://misk.org.sa/en/ | O24: https://misk.org.sa/en/ask-misk-en/ | P24: A | Q24: Cohort mentoring, AI/product strategy, enterprise GTM, founder reviews and Germany/Europe–GCC market access. | R24: External Advisor / Mentor – AI, Product & Germany–GCC | Misk Entrepreneurship | S24: I came across Misk Entrepreneurship at Mohammed bin Salman Foundation (Misk) and its work around entrepreneurship programs supporting young founders, venture development and ecosystem connections. | T24: Use the program/functional email with a concise external mentor/advisor proposition. | U24: Functional / program email | V24: 46291 | W24: Sent | X24: 46291 | Y24: Pitch practical founder mentoring and international-market sessions.
A25: 24 | B25: Saudi Arabia | C25: Makkah Province | D25: Thuwal | E25: Engineering / Technology University | F25: King Abdullah University of Science and Technology (KAUST) | G25: Entrepreneurship Center | H25: KAUST entrepreneurship ecosystem supporting technology founders, startup training and acceleration. | I25: KAUST Entrepreneurship Team | J25: Entrepreneurship Center | K25: leap@kaust.edu.sa | L25: entrepreneurship@kaust.edu.sa | N25: https://leap.kaust.edu.sa/entrepreneurship-center.html | O25: https://www.kaust.edu.sa/ | P25: A | Q25: AI/product strategy, enterprise technology, research commercialization, founder mentoring and Germany–GCC market connections. | R25: External Advisor / Mentor – AI, Product & Germany–GCC | Entrepreneurship Center | S25: I came across Entrepreneurship Center at King Abdullah University of Science and Technology (KAUST) and its work around kaust entrepreneurship ecosystem supporting technology founders, startup training and acceleration. | T25: Use the program/functional email with a concise external mentor/advisor proposition. | U25: Functional / program email | V25: 46291 | W25: Sent | X25: 46291 | Y25: Deep-tech commercialization and international-market fit.
A26: 25 | B26: Saudi Arabia | C26: Makkah Province | D26: Thuwal | E26: Accelerator / Incubator | F26: KAUST | G26: TAQADAM Accelerator | H26: KAUST startup accelerator supporting early-stage ventures with mentoring, training and ecosystem access. | I26: TAQADAM Team | J26: Accelerator team | K26: Apply.Taqadam@kaust.edu.sa | N26: https://taqadam.kaust.edu.sa/ | O26: https://taqadam.kaust.edu.sa/ | P26: A | Q26: Cohort mentoring, AI/product strategy, enterprise GTM, founder reviews and Germany/Europe–GCC market access. | R26: External Advisor / Mentor – AI, Product & Germany–GCC | TAQADAM Accelerator | S26: I came across TAQADAM Accelerator at KAUST and its work around kaust startup accelerator supporting early-stage ventures with mentoring, training and ecosystem access. | T26: Use the program/functional email with a concise external mentor/advisor proposition. | U26: Functional / program email | V26: 46291 | W26: Skipped | Y26: KAUST covered via Entrepreneurship Center email
A27: 26 | B27: Saudi Arabia | C27: Makkah Province | D27: Thuwal | E27: Accelerator / Incubator | F27: KAUST | G27: KAUST Innovation Fund | H27: University-linked venture fund investing in technology startups and spin-ins, including international ventures establishing activity in Saudi Arabia. | I27: KAUST Innovation Fund Team | J27: Innovation Fund | K27: KIF@kaust.edu.sa | L27: entrepreneurship@kaust.edu.sa | N27: https://www.kaust.edu.sa/ | O27: https://www.kaust.edu.sa/en/news/how-kaust-is-enabling-the-in-kingdom-entrepreneurs-of-tomorrow | P27: A | Q27: Cohort mentoring, AI/product strategy, enterprise GTM, founder reviews and Germany/Europe–GCC market access. | R27: External Advisor / Mentor – AI, Product & Germany–GCC | KAUST Innovation Fund | S27: I came across KAUST Innovation Fund at KAUST and its work around university-linked venture fund investing in technology startups and spin-ins, including international ventures establishing activity in saudi arabia. | T27: Use the program/functional email with a concise external mentor/advisor proposition. | U27: Functional / program email | V27: 46291 | W27: Skipped | Y27: KAUST covered via Entrepreneurship Center email
A28: 27 | B28: Saudi Arabia | C28: Riyadh | D28: Riyadh | E28: B-School / University Entrepreneurship | F28: King Saud University | G28: Entrepreneurship Institute | H28: University entrepreneurship institute supporting innovation, entrepreneurial education and venture development. | I28: Dr. Khalid Alhussaini | J28: Executive Director, Entrepreneurship Institute | K28: kalhussaini@ksu.edu.sa | L28: fmalessa@ksu.edu.sa | M28: 011 806 2212 | N28: https://ei.ksu.edu.sa/en/workteam_En | O28: https://ei.ksu.edu.sa/en/workteam_En | P28: A | Q28: Startup mentoring, business models, GTM, enterprise readiness, entrepreneurship education and Germany–GCC connections. | R28: External Advisor / Mentor – AI, Product & Germany–GCC | Entrepreneurship Institute | S28: I came across Entrepreneurship Institute at King Saud University and its work around university entrepreneurship institute supporting innovation, entrepreneurial education and venture development. | T28: Write directly to the named contact using the public email and ask about contributing to the mentor/advisor network. | U28: Named contact + public email | V28: 46291 | W28: Sent | X28: 46291 | Y28: Direct named leadership.
A29: 28 | B29: Saudi Arabia | C29: Makkah Province | D29: Jeddah | E29: Engineering / Technology University | F29: King Abdulaziz University | G29: Center for Innovation & Entrepreneurship | H29: University center supporting innovation, startup creation and entrepreneurship. | I29: Center for Innovation & Entrepreneurship Team | J29: Center team | K29: iec@kau.edu.sa | N29: https://kau.edu.sa/en/page/center-for-innovation-and-entrepreneurship | O29: https://kau.edu.sa/en/page/center-for-innovation-and-entrepreneurship | P29: A | Q29: AI/product strategy, enterprise technology, research commercialization, founder mentoring and Germany–GCC market connections. | R29: External Advisor / Mentor – AI, Product & Germany–GCC | Center for Innovation & Entrepreneurship | S29: I came across Center for Innovation & Entrepreneurship at King Abdulaziz University and its work around university center supporting innovation, startup creation and entrepreneurship. | T29: Use the program/functional email with a concise external mentor/advisor proposition. | U29: Functional / program email | V29: 46291 | W29: Already contacted | Y29: Already emailed in earlier batch (same address)
A30: 29 | B30: Saudi Arabia | C30: Eastern Province | D30: Dhahran | E30: Engineering / Technology University | F30: King Fahd University of Petroleum & Minerals (KFUPM) | G30: Entrepreneurship Institute | H30: Technology university entrepreneurship ecosystem supporting innovation and startup development. | I30: Prof. Wail A. Mousa | J30: Entrepreneurship / faculty contact | K30: wailmousa@kfupm.edu.sa | N30: https://faculty.kfupm.edu.sa/EE/wailmousa/ | O30: https://www.kfupm.edu.sa/ | P30: B | Q30: AI/product strategy, enterprise technology, research commercialization, founder mentoring and Germany–GCC market connections. | R30: External Advisor / Mentor – AI, Product & Germany–GCC | Entrepreneurship Institute | S30: I came across Entrepreneurship Institute at King Fahd University of Petroleum & Minerals (KFUPM) and its work around technology university entrepreneurship ecosystem supporting innovation and startup development. | T30: Write directly to the named contact using the public email and ask about contributing to the mentor/advisor network. | U30: Named contact + public email | V30: 46291 | W30: Skipped | Y30: KFUPM already emailed (ei@kfupm.edu.sa)
A31: 30 | B31: Saudi Arabia | C31: Riyadh | D31: Riyadh | E31: B-School / University Entrepreneurship | F31: Alfaisal University | G31: Center for Innovation, Partnership & Community Engagement (CIPC) | H31: University center connecting innovation, partnerships, entrepreneurship and community/industry engagement. | I31: CIPC Team | J31: Innovation & partnerships team | K31: cipc@alfaisal.edu | M31: +966 11 215 7792 | N31: https://cipc.alfaisal.edu/ | O31: https://cipc.alfaisal.edu/contact-us | P31: A | Q31: Startup mentoring, business models, GTM, enterprise readiness, entrepreneurship education and Germany–GCC connections. | R31: External Advisor / Mentor – AI, Product & Germany–GCC | Alfaisal University | S31: I came across Center for Innovation, Partnership & Community Engagement (CIPC) at Alfaisal University and its work around university center connecting innovation, partnerships, entrepreneurship and community/industry engagement. | T31: Use the program/functional email with a concise external mentor/advisor proposition. | U31: Functional / program email | V31: 46291 | W31: Skipped | Y31: Alfaisal covered via Accelerator email (CIPC in cc)
A32: 31 | B32: Saudi Arabia | C32: Riyadh | D32: Riyadh | E32: Accelerator / Incubator | F32: Alfaisal University | G32: Alfaisal Accelerator | H32: University accelerator supporting venture development and entrepreneurship. | I32: Alfaisal Accelerator Team | J32: Accelerator team | K32: center@alfaisal.edu | M32: +966 11 215 7967 | N32: https://center.alfaisal.edu/accelerator | O32: https://center.alfaisal.edu/accelerator | P32: A | Q32: Cohort mentoring, AI/product strategy, enterprise GTM, founder reviews and Germany/Europe–GCC market access. | R32: External Advisor / Mentor – AI, Product & Germany–GCC | Alfaisal Accelerator | S32: I came across Alfaisal Accelerator at Alfaisal University and its work around university accelerator supporting venture development and entrepreneurship. | T32: Use the program/functional email with a concise external mentor/advisor proposition. | U32: Functional / program email | V32: 46291 | W32: Sent | X32: 46291 | Y32: Direct accelerator route.
A33: 32 | B33: Saudi Arabia | C33: Makkah Province | D33: Jeddah | E33: B-School / University Entrepreneurship | F33: Effat University | G33: Business Innovation & Entrepreneurship Research Center | H33: University research center focused on business innovation and entrepreneurship. | I33: Center Team | J33: Business innovation / entrepreneurship center | N33: https://www.effatuniversity.edu.sa/English/Research/Research-Centers/Business-Innovation-and-Entrepreneurship/Pages/default.aspx | O33: https://www.effatuniversity.edu.sa/English/Research/Research-Centers/Business-Innovation-and-Entrepreneurship/Pages/default.aspx | P33: B | Q33: Startup mentoring, business models, GTM, enterprise readiness, entrepreneurship education and Germany–GCC connections. | R33: External Advisor / Mentor – AI, Product & Germany–GCC | Effat University | S33: I came across Business Innovation & Entrepreneurship Research Center at Effat University and its work around university research center focused on business innovation and entrepreneurship. | T33: Use the official contact/partnership route and ask to be connected to the mentor, partnerships or incubation lead. | U33: Official route – no public email verified | V33: 46291 | W33: Skipped | Y33: No email in database
A34: 33 | B34: Saudi Arabia | C34: Riyadh | D34: Riyadh | E34: B-School / University Entrepreneurship | F34: Prince Sultan University | G34: Entrepreneurship Club | H34: University entrepreneurship community offering student/founder activities and business exposure. | I34: Entrepreneurship Club Team | J34: Entrepreneurship community | K34: epclub@psu.edu.sa | N34: https://www.psu.edu.sa/en/resources | O34: https://www.psu.edu.sa/en/resources | P34: C | Q34: Startup mentoring, business models, GTM, enterprise readiness, entrepreneurship education and Germany–GCC connections. | R34: External Advisor / Mentor – AI, Product & Germany–GCC | Entrepreneurship Club | S34: I came across Entrepreneurship Club at Prince Sultan University and its work around university entrepreneurship community offering student/founder activities and business exposure. | T34: Use the program/functional email with a concise external mentor/advisor proposition. | U34: Functional / program email | V34: 46291 | W34: Sent | X34: 46291 | Y34: Student-facing route; use for workshops/guest mentoring rather than formal board ask.
A35: 34 | B35: Saudi Arabia | C35: Riyadh | D35: Riyadh | E35: Accelerator / Incubator | F35: stc | G35: inspireU | H35: Corporate accelerator supporting digital/technology startups with business support, mentoring and market opportunities. | I35: inspireU Team | J35: Corporate accelerator | N35: https://www.stc.com/en/inspire-u/apply-now.html | O35: https://www.stc.com/en/inspire-u/apply-now.html | P35: B | Q35: Cohort mentoring, AI/product strategy, enterprise GTM, founder reviews and Germany/Europe–GCC market access. | R35: External Advisor / Mentor – AI, Product & Germany–GCC | inspireU | S35: I came across inspireU at stc and its work around corporate accelerator supporting digital/technology startups with business support, mentoring and market opportunities. | T35: Use the official contact/partnership route and ask to be connected to the mentor, partnerships or incubation lead. | U35: Official route – no public email verified | V35: 46291 | W35: Skipped | Y35: No email in database
A36: 35 | B36: Saudi Arabia | C36: Riyadh | D36: Riyadh | E36: Accelerator / Incubator | F36: The Garage | G36: Startup / deep-tech innovation hub | H36: Riyadh startup hub supporting technology founders, accelerators, venture programs and innovation community activity. | I36: The Garage Team | J36: Startup ecosystem team | N36: https://thegarage.sa/ | O36: https://erp.thegarage.sa/contactus | P36: B | Q36: Cohort mentoring, AI/product strategy, enterprise GTM, founder reviews and Germany/Europe–GCC market access. | R36: External Advisor / Mentor – AI, Product & Germany–GCC | Startup / deep-tech innovation hub | S36: I came across Startup / deep-tech innovation hub at The Garage and its work around riyadh startup hub supporting technology founders, accelerators, venture programs and innovation community activity. | T36: Use the official contact/partnership route and ask to be connected to the mentor, partnerships or incubation lead. | U36: Official route – no public email verified | V36: 46291 | W36: Skipped | Y36: No email in database
A37: 36 | B37: Oman | C37: Muscat | D37: Muscat | E37: Government / Startup Ecosystem | F37: Small and Medium Enterprises Development Authority (Riyada) | G37: SME & entrepreneurship ecosystem | H37: Oman government authority supporting SMEs, entrepreneurs, incubators and entrepreneurship programs. | I37: H.E. Halima Al-Zari | J37: Chairperson | K37: Doc@sme.gov.om | L37: support_dpt@sme.gov.om | M37: +968 2202 2222 | N37: https://sme.gov.om/en/ | O37: https://sme.gov.om/en/contact-us/ | P37: A | Q37: Founder capacity building, AI adoption, mentor programs, ecosystem partnerships and Germany/Europe–GCC market connections. | R37: External Mentor / Advisor Support | SME & entrepreneurship ecosystem | S37: I came across SME & entrepreneurship ecosystem at Small and Medium Enterprises Development Authority (Riyada) and its work around oman government authority supporting smes, entrepreneurs, incubators and entrepreneurship programs. | T37: Write directly to the named contact using the public email and ask about contributing to the mentor/advisor network. | U37: Named contact + public email | V37: 46291 | W37: Sent | X37: 46291 | Y37: Government-level ecosystem target; use concise partnership/mentor proposition.
A38: 37 | B38: Oman | C38: Muscat | D38: Muscat | E38: Government / Startup Ecosystem | F38: ITHCA Group | G38: Technology investment & innovation ecosystem | H38: Oman technology investment group supporting ICT, innovation, digital businesses and national technology development. | I38: ITHCA Team | J38: Innovation / investment ecosystem | K38: info@ithca.om | M38: +968 2231 0500 | N38: https://ithca.om/ | O38: https://ithca.om/contact/ | P38: A | Q38: Founder capacity building, AI adoption, mentor programs, ecosystem partnerships and Germany/Europe–GCC market connections. | R38: External Mentor / Advisor Support | ITHCA Group | S38: I came across Technology investment & innovation ecosystem at ITHCA Group and its work around oman technology investment group supporting ict, innovation, digital businesses and national technology development. | T38: Use the program/functional email with a concise external mentor/advisor proposition. | U38: Functional / program email | V38: 46291 | W38: Sent | X38: 46291 | Y38: Strong enterprise-tech and international ecosystem fit.
A39: 38 | B39: Oman | C39: Muscat | D39: Muscat | E39: Accelerator / Incubator | F39: Oman Technology Fund (OTF) | G39: Technology investment / acceleration | H39: Technology investment platform supporting innovative technology ventures and ecosystem development. | I39: OTF Team | J39: Investment / accelerator team | K39: info@otf.om | M39: +968 2417 2717 | N39: https://www.otf.om/ | O39: https://www.otf.om/__trashed-3/contact/ | P39: A | Q39: Cohort mentoring, AI/product strategy, enterprise GTM, founder reviews and Germany/Europe–GCC market access. | R39: External Advisor / Mentor – AI, Product & Germany–GCC | Technology investment / acceleration | S39: I came across Technology investment / acceleration at Oman Technology Fund (OTF) and its work around technology investment platform supporting innovative technology ventures and ecosystem development. | T39: Use the program/functional email with a concise external mentor/advisor proposition. | U39: Functional / program email | V39: 46291 | W39: Sent | X39: 46291 | Y39: Pitch startup reviews, AI/product mentoring and international-market support.
A40: 39 | B40: Oman | C40: Muscat | D40: Muscat | E40: Government / Startup Ecosystem | F40: Oman Startup Hub | G40: National startup ecosystem platform | H40: Digital startup ecosystem platform connecting founders, advisors, investors and support organizations in Oman. | I40: Oman Startup Hub Team | J40: Startup ecosystem team | K40: support@omanstartuphub.om | N40: https://omanstartuphub.om/ | O40: https://omanstartuphub.om/contact-us | P40: A | Q40: Founder capacity building, AI adoption, mentor programs, ecosystem partnerships and Germany/Europe–GCC market connections. | R40: External Mentor / Advisor Support | National startup ecosystem platform | S40: I came across National startup ecosystem platform at Oman Startup Hub and its work around digital startup ecosystem platform connecting founders, advisors, investors and support organizations in oman. | T40: Use the program/functional email with a concise external mentor/advisor proposition. | U40: Functional / program email | V40: 46291 | W40: Sent | X40: 46291 | Y40: Advisor network makes this directly aligned with your objective.
...

Sheet Mail Ready
A1: Country | B1: Region | C1: Category | D1: Organisation | E1: Program / Unit | F1: Contact Name | G1: Contact Role | H1: Primary Email | I1: Alternate Email | J1: Priority | K1: Suggested Subject | L1: Personalization Hook | M1: Profile / Contact URL | N1: Email Status
A2: UAE | B2: Abu Dhabi | C2: Accelerator / Incubator | D2: Hub71 | E2: Hub71 startup ecosystem | F2: Hub71 Team | G2: Ecosystem / startup team | H2: info@hub71.com | J2: A | K2: External Advisor / Mentor – AI, Product & Germany–GCC | Hub71 startup ecosystem | L2: I came across Hub71 startup ecosystem at Hub71 and its work around abu dhabi global tech ecosystem offering startup programs, market access, investor and corporate connections. | M2: https://www.hub71.com/ | N2: Already contacted
A3: UAE | B3: Abu Dhabi | C3: Accelerator / Incubator | D3: startAD – NYU Abu Dhabi | E3: startAD | F3: Ashwin Joshi | G3: Director, startAD | H3: startAD@nyu.edu | J3: A | K3: External Advisor / Mentor – AI, Product & Germany–GCC | startAD | L3: I came across startAD at startAD – NYU Abu Dhabi and its work around nyu abu dhabi-based accelerator and innovation platform connecting startups, corporates, investors and mentors. | M3: https://startad.ae/ | N3: Already contacted
A4: UAE | B4: Dubai | C4: Accelerator / Incubator | D4: Dubai Technology Entrepreneur Campus (Dtec) | E4: Dtec | F4: Dtec Team | G4: Startup / ecosystem team | H4: dtec.sales@dtec.ae | I4: community@dtec.ae | J4: A | K4: External Advisor / Mentor – AI, Product & Germany–GCC | Dtec | L4: I came across Dtec at Dubai Technology Entrepreneur Campus (Dtec) and its work around dubai silicon oasis technology startup hub offering incubation, workspace, market access and ecosystem support. | M4: https://dtec.ae/ | N4: Skipped
A5: UAE | B5: Dubai | C5: Government / Startup Ecosystem | D5: Mohammed Bin Rashid Innovation Fund (MBRIF) | E5: Innovation Accelerator | F5: MBRIF Team | G5: Innovation / accelerator team | H5: contact@mbrif.ae | I5: info@mbrinnovationfund.ae | J5: A | K5: External Mentor / Advisor Support | Innovation Accelerator | L5: I came across Innovation Accelerator at Mohammed Bin Rashid Innovation Fund (MBRIF) and its work around uae ministry of finance initiative supporting innovative companies through acceleration and growth services. | M5: https://mbrif.ae/ | N5: Sent
A6: UAE | B6: Sharjah | C6: Accelerator / Incubator | D6: Sharjah Entrepreneurship Center (Sheraa) | E6: Sheraa | F6: Sara Abdelaziz Al Nuaimi | G6: CEO | H6: info@sheraa.ae | J6: A | K6: External Advisor / Mentor – AI, Product & Germany–GCC | Sheraa | L6: I came across Sheraa at Sharjah Entrepreneurship Center (Sheraa) and its work around sharjah startup ecosystem builder supporting founders through programs, incubation, mentorship and market access. | M6: https://sheraa.ae/about-us | N6: Already contacted
A7: UAE | B7: Dubai | C7: Government / Startup Ecosystem | D7: Dubai Chamber of Digital Economy | E7: Digital Economy ecosystem | F7: Digital Economy Team | G7: Customer / ecosystem team | H7: customercare@dubaichamber.com | J7: A | K7: External Mentor / Advisor Support | Digital Economy ecosystem | L7: I came across Digital Economy ecosystem at Dubai Chamber of Digital Economy and its work around dubai chambers entity supporting digital companies, startups, market entry and ecosystem development. | M7: https://www.dubaichamber.com/ | N7: Skipped
A8: UAE | B8: Abu Dhabi | C8: Government / Startup Ecosystem | D8: Khalifa Fund for Enterprise Development | E8: Entrepreneurship support | F8: Khalifa Fund Team | G8: Entrepreneurship support team | H8: info@khalifafund.ae | J8: A | K8: External Mentor / Advisor Support | Entrepreneurship support | L8: I came across Entrepreneurship support at Khalifa Fund for Enterprise Development and its work around abu dhabi government entity supporting entrepreneurship, sme development, capability building and market access. | M8: https://www.khalifafund.ae/ | N8: Sent
A9: UAE | B9: Sharjah | C9: Government / Startup Ecosystem | D9: Sharjah SME – RUWAD | E9: Entrepreneurship support | F9: RUWAD Team | G9: SME / entrepreneurship team | H9: info@ruwad.ae | I9: cs@ruwad.ae | J9: A | K9: External Mentor / Advisor Support | Entrepreneurship support | L9: I came across Entrepreneurship support at Sharjah SME – RUWAD and its work around sharjah government sme development body supporting entrepreneurs through advisory, training and business support. | M9: https://www.ruwad.ae/ | N9: Sent
A10: UAE | B10: Dubai | C10: B-School / University Entrepreneurship | D10: University of Dubai | E10: Innovation, Entrepreneurship & Business Centre (IEBC) | F10: IEBC Team | G10: Entrepreneurship & incubation team | H10: Info.iebc@ud.ac.ae | I10: startup.support@ud.ac.ae | J10: A | K10: External Advisor / Mentor – AI, Product & Germany–GCC | University of Dubai | L10: I came across Innovation, Entrepreneurship & Business Centre (IEBC) at University of Dubai and its work around university entrepreneurship centre offering pitch competitions, workshops, mentoring, incubation and ecosystem connections. | M10: https://ud.ac.ae/entrepreneurship-and-business-centre-udiebc/ | N10: Already contacted
A11: UAE | B11: Abu Dhabi | C11: Engineering / Technology University | D11: Khalifa University | E11: Technology Management & Innovation | F11: Aysha Ali Rashed AlNuaimi | G11: Acting Director, Technology Management & Innovation | H11: aysha.alnuaimi@ku.ac.ae | I11: ip@ku.ac.ae | J11: A | K11: External Advisor / Mentor – AI, Product & Germany–GCC | Technology Management & Innovation | L11: I came across Technology Management & Innovation at Khalifa University and its work around university office responsible for research commercialization, startups, licensing and industry engagement. | M11: https://www.ku.ac.ae/research-offices/technology-management-innovation/our-team | N11: Sent
A12: UAE | B12: Abu Dhabi | C12: Engineering / Technology University | D12: Mohamed bin Zayed University of Artificial Intelligence (MBZUAI) | E12: Incubation & Entrepreneurship Center (IEC) | F12: IEC Team | G12: Incubation & Entrepreneurship Center | H12: iec@mbzuai.ac.ae | I12: info@mbzuai.ac.ae | J12: A | K12: External Advisor / Mentor – AI, Product & Germany–GCC | Mohamed bin Zayed University of Artificial Intelligence (MBZUAI) | L12: I came across Incubation & Entrepreneurship Center (IEC) at Mohamed bin Zayed University of Artificial Intelligence (MBZUAI) and its work around ai university incubation center helping founders build and scale ai startups, with mentor and ecosystem partner networks. | M12: https://mbzuai.ac.ae/innovation-partnerships/incubation-entrepreneurship-center | N12: Sent
A13: UAE | B13: Sharjah | C13: Engineering / Technology University | D13: University of Sharjah | E13: Innovation Hub | F13: Engr. Mahmoud Abu Shammeh | G13: Director, Innovation Hub | H13: abushammeh@sharjah.ac.ae | I13: mmadi@sharjah.ac.ae | J13: A | K13: External Advisor / Mentor – AI, Product & Germany–GCC | Innovation Hub | L13: I came across Innovation Hub at University of Sharjah and its work around university innovation hub supporting entrepreneurship, technology development and commercialization. | M13: https://www.sharjah.ac.ae/en/Services/Departments/Innovation-Hub | N13: Sent
A14: UAE | B14: Abu Dhabi | C14: B-School / University Entrepreneurship | D14: United Arab Emirates University (UAEU) | E14: Emirates Centre for Entrepreneurship Research | F14: Dr. Ishara Maharaj | G14: Entrepreneurship research contact | H14: ishara.maharaj@uaeu.ac.ae | I14: savagepd@uaeu.ac.ae | J14: B | K14: External Advisor / Mentor – AI, Product & Germany–GCC | United Arab Emirates University (UAEU) | L14: I came across Emirates Centre for Entrepreneurship Research at United Arab Emirates University (UAEU) and its work around university entrepreneurship research ecosystem linking entrepreneurship, education, research and enterprise development. | M14: https://www.uaeu.ac.ae/en/research/ | N14: Sent
A15: UAE | B15: Dubai | C15: Engineering / Technology University | D15: Rochester Institute of Technology Dubai (RIT Dubai) | E15: Projects & Development / entrepreneurship ecosystem | F15: Yousef Al Mannaee | G15: Projects & Development Manager | H15: yaacad@rit.edu | I15: dubai@rit.edu | J15: A | K15: External Advisor / Mentor – AI, Product & Germany–GCC | Rochester Institute of Technology Dubai (RIT Dubai) | L15: I came across Projects & Development / entrepreneurship ecosystem at Rochester Institute of Technology Dubai (RIT Dubai) and its work around technology-focused dubai campus with industry projects and entrepreneurship-oriented activities. | M15: https://www.rit.edu/dubai/directory | N15: Sent
A16: UAE | B16: Dubai | C16: B-School / University Entrepreneurship | D16: SP Jain School of Global Management | E16: Dubai Campus | F16: Amol Sawant | G16: Dubai campus contact | H16: amol.sawant@spjain.org | I16: admissions.dxb@spjain.org | J16: B | K16: External Advisor / Mentor – AI, Product & Germany–GCC | Dubai Campus | L16: I came across Dubai Campus at SP Jain School of Global Management and its work around global business school with dubai campus and entrepreneurship/business programs. | M16: https://www.spjain.org/global-campus/dubai | N16: Sent
A17: Saudi Arabia | B17: Riyadh | C17: Government / Startup Ecosystem | D17: Monsha'at – Small and Medium Enterprises General Authority | E17: Innovation Center | F17: Monsha'at Innovation Center Team | G17: Innovation Center | H17: InnovationCenters@monshaat.gov.sa | I17: Info@monshaat.gov.sa | J17: A | K17: External Mentor / Advisor Support | Innovation Center | L17: I came across Innovation Center at Monsha'at – Small and Medium Enterprises General Authority and its work around saudi government innovation centers supporting technology startups through incubation, consultations, workshops and expert guidance. | M17: https://www.monshaat.gov.sa/en/innovation_center | N17: Sent
A18: Saudi Arabia | B18: Riyadh | C18: Government / Startup Ecosystem | D18: Ministry of Communications and Information Technology (MCIT) | E18: CODE Gate | F18: CODE / MCIT Team | G18: Technology entrepreneurship team | H18: info@mcit.gov.sa | J18: A | K18: External Mentor / Advisor Support | CODE Gate | L18: I came across CODE Gate at Ministry of Communications and Information Technology (MCIT) and its work around government technology entrepreneurship platform supporting digital startups and innovation programs. | M18: https://code.mcit.gov.sa/ | N18: Skipped
A19: Saudi Arabia | B19: Riyadh | C19: Government / Startup Ecosystem | D19: Ministry of Communications and Information Technology (MCIT) | E19: Tech Founders | F19: Tech Founders Team | G19: Technology entrepreneurship program | H19: info@mcit.gov.sa | J19: B | K19: External Mentor / Advisor Support | Tech Founders | L19: I came across Tech Founders at Ministry of Communications and Information Technology (MCIT) and its work around mcit technology entrepreneurship program supporting startup founders and technology venture development. | M19: https://www.mcit.gov.sa/ | N19: Skipped
A20: Saudi Arabia | B20: Riyadh | C20: Accelerator / Incubator | D20: Mohammed bin Salman Foundation (Misk) | E20: Misk Entrepreneurship | F20: Misk Entrepreneurship Team | G20: Entrepreneurship team | H20: contact@misk.org.sa | J20: A | K20: External Advisor / Mentor – AI, Product & Germany–GCC | Misk Entrepreneurship | L20: I came across Misk Entrepreneurship at Mohammed bin Salman Foundation (Misk) and its work around entrepreneurship programs supporting young founders, venture development and ecosystem connections. | M20: https://misk.org.sa/en/ | N20: Sent
