Workbook

Sheet Dashboard
A1: India Startup & University Advisor Outreach Database – Madhiyazhagan
A2: Engineering universities • B-Schools • Accelerators/Incubators • State/UT startup missions | Verified/curated 26 Sep 2026
A4: Database KPI | B4: Value | D4: Outreach Readiness | E4: Value
A5: Total targets | B5: =COUNTA('Master Mail List'!A2:A131) -> 130 | D5: Priority A | E5: =COUNTIF('Master Mail List'!N2:N131,"A") -> 93
A6: States / UTs represented | B6: 31 | D6: Named contact + email | E6: =COUNTIF('Master Mail List'!R2:R131,"Named contact + email") -> 54
A7: Engineering / Technology | B7: =COUNTIF('Master Mail List'!D2:D131,"Engineering / Technology University") -> 49 | D7: Functional / office email | E7: =COUNTIF('Master Mail List'!R2:R131,"Functional / office email") -> 72
A8: B-Schools | B8: =COUNTIF('Master Mail List'!D2:D131,"B-School") -> 18 | D8: No public email verified | E8: =COUNTIF('Master Mail List'!R2:R131,"No public email verified") -> 4
A9: Accelerators / Incubators | B9: =COUNTIF('Master Mail List'!D2:D131,"Accelerator / Incubator") -> 33 | D9: Emails sent | E9: =COUNTIF('Master Mail List'!T2:T131,"Sent") -> 86
A10: Govt Startup Missions | B10: =COUNTIF('Master Mail List'!D2:D131,"State / UT Government Startup Mission") -> 30
A11: Rows with primary email | B11: 126
A14: Category | B14: Targets
A15: Engineering / Technology University | B15: =COUNTIF('Master Mail List'!D2:D131,A15) -> 49
A16: B-School | B16: =COUNTIF('Master Mail List'!D2:D131,A16) -> 18
A17: Accelerator / Incubator | B17: =COUNTIF('Master Mail List'!D2:D131,A17) -> 33
A18: State / UT Government Startup Mission | B18: =COUNTIF('Master Mail List'!D2:D131,A18) -> 30

Sheet Master Mail List
A1: ID | B1: State / UT | C1: City | D1: Category | E1: Institution / Organisation | F1: Incubator / Program / Unit | G1: Contact Name | H1: Contact Role | I1: Primary Email | J1: CC / Alternate Email | K1: Phone | L1: Contact / Profile URL | M1: Official Source URL | N1: Priority | O1: Why Madhi Fits | P1: Suggested Subject | Q1: Best Entry Route | R1: Contact Quality | S1: Verified On | T1: Email Status | U1: Last Contacted | V1: Notes
A2: 1 | B2: Andhra Pradesh | C2: Visakhapatnam | D2: B-School | E2: IIM Visakhapatnam | F2: FIELD – IIMV Foundation for Incubation Entrepreneurial Learning & Development | G2: FIELD Team | H2: Incubation team | I2: incubationcenter@iimv.ac.in | K2: +91 75693 09208 | L2: https://iimvfield.com/contact-us/ | M2: https://iimvfield.com/contact-us/ | N2: A | O2: Product strategy, enterprise GTM, founder mentoring, India–Europe market access. | P2: External Advisor / Mentor – AI, Product & India–Europe Market Access | FIELD | Q2: Email FIELD and request External Advisor / Mentor Panel consideration. | R2: Functional / office email | S2: 46291 | T2: Already contacted | V2: Already emailed in earlier batch (same address)
A3: 2 | B3: Andhra Pradesh | C3: Sri City | D3: Engineering / Technology University | E3: IIIT Sri City | F3: Gyan Circle Ventures | G3: Gyan Circle Ventures Team | H3: Incubation team | I3: gcv.manager@iiits.in | L3: https://msh.meity.gov.in/tide/incubatorslist | M3: https://msh.meity.gov.in/tide/incubatorslist | N3: A | O3: AI/cloud platforms, enterprise architecture, deep-tech commercialization, startup mentoring. | P3: External Advisor / Mentor – AI, Product & India–Europe Market Access | Gyan Circle Ventures | Q3: Email the incubation manager with a focused AI/platform + cross-border advisory proposition. | R3: Functional / office email | S3: 46291 | T3: Sent | U3: 46291
A4: 3 | B4: Andhra Pradesh | C4: Visakhapatnam | D4: State / UT Government Startup Mission | E4: Andhra Pradesh Innovation Society | F4: AP Innovation & Startup Mission | G4: AP Innovation Society Team | H4: State startup nodal agency | I4: innovationsociety@ap.gov.in | K4: +91 7396603335 | L4: https://www.startupindia.gov.in/content/sih/en/state-startup-policies/Andhra-Pradesh-state-policy.html | M4: https://www.startupindia.gov.in/content/sih/en/state-startup-policies/Andhra-Pradesh-state-policy.html | N4: A | O4: Mentor/advisor contribution to state startup programs, founder capacity building, AI adoption, international ecosystem connections. | P4: External Advisor / Mentor Support for AP Innovation & Startup Mission | Q4: Email the state startup / innovation team with a concise advisor profile and offer specific mentor contributions. | R4: Functional / office email | S4: 46291 | T4: Sent | U4: 46291 | V4: Government / state ecosystem target
A5: 4 | B5: Arunachal Pradesh | C5: Nirjuli | D5: Engineering / Technology University | E5: NERIST | F5: Incubation & Entrepreneurship Cell (IEC) | G5: Prof. Ningrinla Marchang | H5: Coordinator, Incubation & Entrepreneurship Cell | I5: nm@nerist.ac.in | L5: https://nerist.ac.in/facilities/sric/incubation-entrepreneurship/ | M5: https://nerist.ac.in/facilities/sric/incubation-entrepreneurship/ | N5: B | O5: Entrepreneurship education, venture review, AI/product workshops, founder mentoring. | P5: External Advisor / Mentor – AI, Product & India–Europe Market Access | Incubation & Entrepreneurship Cell (IEC) | Q5: Write directly to the Coordinator requesting empanelment as an external advisor/mentor. | R5: Named contact + email | S5: 46291 | T5: Sent | U5: 46291
A6: 5 | B6: Arunachal Pradesh | C6: Itanagar | D6: State / UT Government Startup Mission | E6: Arunachal Pradesh Innovation and Investment Park (APIIP) | F6: State Startup Mission | G6: APIIP Startup Team | H6: State startup nodal agency | I6: arunachal.startups@gmail.com | K6: +91 94352 78774 | L6: https://www.startupindia.gov.in/content/sih/en/state-startup-policies/Arunachal-Pradesh-state-policy.html | M6: https://www.startupindia.gov.in/content/sih/en/state-startup-policies/Arunachal-Pradesh-state-policy.html | N6: B | O6: Mentor/advisor contribution to state startup programs, founder capacity building, AI adoption, international ecosystem connections. | P6: External Advisor / Mentor Support for State Startup Mission | Q6: Email the state startup / innovation team with a concise advisor profile and offer specific mentor contributions. | R6: Functional / office email | S6: 46291 | T6: Sent | U6: 46291 | V6: Government / state ecosystem target
A7: 6 | B7: Assam | C7: Tezpur | D7: Accelerator / Incubator | E7: Tezpur University | F7: Centre for Innovation Incubation and Entrepreneurship (CIIE) | G7: Dr. M. K. Hazarika | H7: Head, CIIE | I7: headciie@tezu.ernet.in | J7: mkhazarika@tezu.ernet.in | L7: https://www.tezu.ac.in/contact/edc.html | M7: https://www.tezu.ac.in/contact/edc.html | N7: B | O7: AI/data, digital platforms, commercialization, entrepreneurship education, market linkage. | P7: External Advisor / Mentor – AI, Product & India–Europe Market Access | Centre for Innovation Incubation and Entrepreneurship (CIIE) | Q7: Write to the Head with a one-page advisor profile and proposed quarterly mentoring format. | R7: Named contact + email | S7: 46291 | T7: Sent | U7: 46291
A8: 7 | B8: Assam | C8: Guwahati | D8: Engineering / Technology University | E8: IIT Guwahati | F8: Technology Incubation Centre (TIC) | G8: TIC Team | H8: Incubation office | I8: tic@iitg.ac.in | K8: +91 361 2583194 / 2583191 | L8: https://iitgtic.com/index_contacts | M8: https://iitgtic.com/index_contacts | N8: A | O8: AI/cloud/platform architecture, product scaling, enterprise adoption, founder mentoring. | P8: External Advisor / Mentor – AI, Product & India–Europe Market Access | Technology Incubation Centre (TIC) | Q8: Email TIC with an advisor profile and areas: AI, cloud, enterprise SaaS, Europe market access. | R8: Functional / office email | S8: 46291 | T8: Already contacted | V8: Already emailed in earlier batch (same address)
A9: 8 | B9: Assam | C9: Guwahati | D9: State / UT Government Startup Mission | E9: Startup Assam | F9: The Nest / State Startup Mission | G9: Startup Assam Team | H9: State startup mission | I9: startupassam2018@gmail.com | J9: coo.assamstartup@iimcip.org | K9: 1800 345 3957 | L9: https://www.startupindia.gov.in/content/sih/en/state-startup-policies/Assam-state-policy.html | M9: https://www.startupindia.gov.in/content/sih/en/state-startup-policies/Assam-state-policy.html | N9: A | O9: Mentor/advisor contribution to state startup programs, founder capacity building, AI adoption, international ecosystem connections. | P9: External Advisor / Mentor Support for The Nest / State Startup Mission | Q9: Email the state startup / innovation team with a concise advisor profile and offer specific mentor contributions. | R9: Functional / office email | S9: 46291 | T9: Sent | U9: 46291 | V9: Government / state ecosystem target
A10: 9 | B10: Bihar | C10: Patna | D10: Accelerator / Incubator | E10: B-HUB | F10: CIMP Business Incubation & Innovation Foundation Hub | G10: B-HUB Team | H10: Incubation / co-learning hub | I10: enquiry@bhub.org.in | K10: +91 9128712345 | L10: https://www.bhub.org.in/contact-us/ | M10: https://www.bhub.org.in/contact-us/ | N10: A | O10: Startup mentoring, product/GTM, AI adoption, enterprise connects, international ecosystem access. | P10: External Advisor / Mentor – AI, Product & India–Europe Startup Ecosystem | CIMP Business Incubation & Innovation Foundation Hub | Q10: Write directly to the named contact or functional incubation inbox; offer specific advisor/mentor contribution rather than asking for a job. | R10: Functional / office email | S10: 46291 | T10: Sent | U10: 46291 | V10: Additional high-value target
A11: 10 | B11: Bihar | C11: Patna | D11: Engineering / Technology University | E11: IIT Patna | F11: Incubation Centre IIT Patna | G11: Mr. Gopi Krishna Sakhinala | H11: Incubation contact | I11: iciitp@iitp.ac.in | K11: +91 79709 72747 | L11: https://iciitp.com/index.php/contact/ | M11: https://iciitp.com/index.php/contact/ | N11: A | O11: AI/cloud, platform engineering, enterprise transformation, commercialization, mentoring. | P11: External Advisor / Mentor – AI, Product & India–Europe Market Access | Incubation Centre IIT Patna | Q11: Email the centre and reference interest in external advisor / startup review panel roles. | R11: Named contact + email | S11: 46291 | T11: Already contacted | V11: Already emailed in earlier batch (same address)
A12: 11 | B12: Bihar | C12: Patna | D12: Engineering / Technology University | E12: NIT Patna | F12: Incubation Center NIT Patna | G12: Incubation Center Team | H12: Incubation office | I12: Incubation@nitp.ac.in | L12: https://incubationcenter.nitp.ac.in/ | M12: https://incubationcenter.nitp.ac.in/ | N12: B | O12: AI/product mentoring, enterprise software, startup readiness, student entrepreneurship. | P12: External Advisor / Mentor – AI, Product & India–Europe Market Access | Incubation Center NIT Patna | Q12: Request an external mentor/advisor association and offer AI/product/GTM sessions for incubatees. | R12: Functional / office email | S12: 46291 | T12: Sent | U12: 46291
A13: 12 | B13: Bihar | C13: Patna | D13: State / UT Government Startup Mission | E13: Startup Bihar – Department of Industries | F13: State Startup Mission | G13: Alok Ranjan Ghosh | H13: Director Industries | I13: startup-bihar@gov.in | J13: dir.ind-bih@nic.in | K13: 1800 345 6214 | L13: https://startup.bihar.gov.in/ | M13: https://startup.bihar.gov.in/ | N13: A | O13: Mentor/advisor contribution to state startup programs, founder capacity building, AI adoption, international ecosystem connections. | P13: External Advisor / Mentor Support for State Startup Mission | Q13: Email the state startup / innovation team with a concise advisor profile and offer specific mentor contributions. | R13: Named contact + email | S13: 46291 | T13: Sent | U13: 46291 | V13: Government / state ecosystem target
A14: 13 | B14: Chhattisgarh | C14: Naya Raipur | D14: Engineering / Technology University | E14: IIIT Naya Raipur | F14: Foundation for Technology & Business Incubation / Entrepreneurship | G14: Dr. Amit Agarwal | H14: Incubation contact | I14: amitag@iiitnr.edu.in | K14: +91 89541 67407 | L14: https://www.invest.cg.gov.in/startup | M14: https://www.invest.cg.gov.in/startup | N14: B | O14: AI/cloud architecture, enterprise platforms, tech commercialization, startup coaching. | P14: External Advisor / Mentor – AI, Product & India–Europe Market Access | Foundation for Technology & Business Incubation / Entrepreneurship | Q14: Write to Dr. Agarwal requesting consideration for external advisor/mentor pool. | R14: Named contact + email | S14: 46291 | T14: Sent | U14: 46291
A15: 14 | B15: Chhattisgarh | C15: Bhilai | D15: Engineering / Technology University | E15: IIT Bhilai | F15: IIT Bhilai Innovation & Technology Foundation (IBITF) | G15: Prof. Souradyuti Paul | H15: Incubation / innovation contact | I15: tih@iitbhilai.ac.in | K15: +91 99710 02706 | L15: https://www.invest.cg.gov.in/startup | M15: https://www.invest.cg.gov.in/startup | N15: A | O15: AI, cloud, platform strategy, deep-tech commercialization, enterprise partnerships. | P15: External Advisor / Mentor – AI, Product & India–Europe Market Access | IIT Bhilai Innovation & Technology Foundation (IBITF) | Q15: Contact the innovation foundation and propose external advisory support for AI/digital ventures. | R15: Named contact + email | S15: 46291 | T15: Sent | U15: 46291
A16: 15 | B16: Chhattisgarh | C16: Raipur | D16: Engineering / Technology University | E16: NIT Raipur | F16: NIT Raipur Foundation for Innovation & Entrepreneurship (NITRRFIE) | G16: Medha Singh | H16: Incubation contact | I16: nitrrfie@nitrr.ac.in | K16: +91 94062 02248 | L16: https://www.invest.cg.gov.in/startup | M16: https://www.invest.cg.gov.in/startup | N16: B | O16: AI/product strategy, venture review, enterprise partnerships, entrepreneurship mentoring. | P16: External Advisor / Mentor – AI, Product & India–Europe Market Access | NIT Raipur Foundation for Innovation & Entrepreneurship (NITRRFIE) | Q16: Email the named contact with advisor CV and proposed monthly founder office hours. | R16: Named contact + email | S16: 46291 | T16: Sent | U16: 46291
A17: 16 | B17: Chhattisgarh | C17: Raipur | D17: State / UT Government Startup Mission | E17: Startup Chhattisgarh – Directorate of Industries | F17: State Startup Mission | G17: Suman Dewangan | H17: Deputy Director – Startup | I17: startup.cg@gov.in | J17: invest-support@cg.gov.in | K17: 0771-3101500 | L17: https://www.invest.cg.gov.in/startup | M17: https://www.invest.cg.gov.in/startup | N17: A | O17: Mentor/advisor contribution to state startup programs, founder capacity building, AI adoption, international ecosystem connections. | P17: External Advisor / Mentor Support for State Startup Mission | Q17: Email the state startup / innovation team with a concise advisor profile and offer specific mentor contributions. | R17: Named contact + email | S17: 46291 | T17: Sent | U17: 46291 | V17: Government / state ecosystem target
A18: 17 | B18: Delhi | C18: New Delhi | D18: Engineering / Technology University | E18: IIIT Delhi | F18: IIIT Delhi Innovation & Incubation Center (IIITD-IC) | G18: IIITD Innovation & Incubation Center | H18: Incubation office | I18: info@iiitdic.in | L18: https://msh.meity.gov.in/tide/incubatorslist | M18: https://msh.meity.gov.in/tide/incubatorslist | N18: A | O18: AI/software platforms, product architecture, SaaS scaling, enterprise GTM, mentoring. | P18: External Advisor / Mentor – AI, Product & India–Europe Market Access | IIIT Delhi Innovation & Incubation Center (IIITD-IC) | Q18: Email with a proposal to join the mentor/advisor network for AI/software ventures. | R18: Functional / office email | S18: 46291 | T18: Already contacted | V18: Already emailed in earlier batch (same address)
A19: 18 | B19: Delhi | C19: New Delhi | D19: Engineering / Technology University | E19: IIT Delhi | F19: FITT – Foundation for Innovation and Technology Transfer | G19: Dr. Ashutosh Pastor | H19: Vice President – Incubation | I19: AshutoshPastor@fitt-iitd.in | L19: https://fitt-iitd.in/web/fittteam | M19: https://fitt-iitd.in/web/fittteam | N19: A | O19: Deep-tech commercialization, corporate innovation, AI/cloud strategy, international market access. | P19: External Advisor / Mentor – AI, Product & India–Europe Market Access | FITT | Q19: Write directly to VP Incubation; attach concise advisor bio and specify AI/cloud, enterprise GTM and India–Europe bridge. | R19: Named contact + email | S19: 46291 | T19: Skipped | V19: Already emailed FITT (mdfitt@gmail.com)
A20: 19 | B20: Delhi | C20: New Delhi | D20: Engineering / Technology University | E20: Netaji Subhas University of Technology (NSUT) | F20: NSUT Incubation & Innovation Foundation | G20: NSUT-IIF Team | H20: Incubation foundation | I20: nsutiif@nsut.ac.in | J20: connect.nsutiif@nsut.ac.in | K20: +91 9205475058 | L20: https://nsutiif.in/contact | M20: https://nsutiif.in/contact | N20: A | O20: AI/product strategy, enterprise technology, commercialization, corporate partnerships, India–Europe market access. | P20: External Advisor / Mentor – AI, Product & India–Europe Startup Ecosystem | NSUT Incubation & Innovation Foundation | Q20: Write directly to the named contact or functional incubation inbox; offer specific advisor/mentor contribution rather than asking for a job. | R20: Functional / office email | S20: 46291 | T20: Sent | U20: 46291 | V20: Additional high-value target
A21: 20 | B21: Goa | C21: Sanquelim | D21: B-School | E21: Goa Institute of Management | F21: Atal Incubation Centre – GIM Foundation (AIC-GIM) | G21: AIC-GIM Team | H21: Startup / incubation team | I21: startups@aicgim.in | K21: +91 832 2366700 | L21: https://aicgim.in/ | M21: https://aicgim.in/ | N21: A | O21: Startup strategy, enterprise GTM, AI adoption, founder mentoring, India–Europe linkage. | P21: External Advisor / Mentor – AI, Product & India–Europe Market Access | Atal Incubation Centre | Q21: Email the startup team requesting inclusion as an external advisor/mentor, especially for technology and scale-up cohorts. | R21: Functional / office email | S21: 46291 | T21: Sent | U21: 46291
A22: 21 | B22: Goa | C22: Zuarinagar | D22: Engineering / Technology University | E22: BITS Pilani – Goa Campus | F22: CIIE / BGIIES | G22: Prof. Saroj Sundar Baral | H22: Faculty-in-Charge, CIIE | I22: ssbaral@goa.bits-pilani.ac.in | K22: +91 832 2580119 | L22: https://www.bits-pilani.ac.in/goa/ciie/ | M22: https://www.bits-pilani.ac.in/goa/ciie/ | N22: A | O22: Technology commercialization, AI/product strategy, entrepreneurship education, mentor programs. | P22: External Advisor / Mentor – AI, Product & India–Europe Market Access | CIIE / BGIIES | Q22: Write to the Faculty-in-Charge proposing advisory sessions, venture reviews and India–Europe startup connects. | R22: Named contact + email | S22: 46291 | T22: Sent | U22: 46291
A23: 22 | B23: Goa | C23: Panaji | D23: State / UT Government Startup Mission | E23: Startup Goa – Department of Information Technology | F23: Startup Promotion Cell | G23: Startup Promotion Cell Team | H23: State startup nodal agency | I23: spc-dit.goa@gov.in | K23: 1800-233-5060 | L23: https://www.startupindia.gov.in/content/sih/en/state-startup-policies/Goa-state-policy.html | M23: https://www.startupindia.gov.in/content/sih/en/state-startup-policies/Goa-state-policy.html | N23: B | O23: Mentor/advisor contribution to state startup programs, founder capacity building, AI adoption, international ecosystem connections. | P23: External Advisor / Mentor Support for Startup Promotion Cell | Q23: Email the state startup / innovation team with a concise advisor profile and offer specific mentor contributions. | R23: Functional / office email | S23: 46291 | T23: Sent | U23: 46291 | V23: Government / state ecosystem target
A24: 23 | B24: Gujarat | C24: Ahmedabad | D24: Accelerator / Incubator | E24: Gujarat University | F24: Gujarat University Startup & Entrepreneurship Council (GUSEC) | G24: GUSEC Partnerships Team | H24: Partnerships / incubation | I24: partnerships@gusec.edu.in | J24: contact@gusec.edu.in | L24: https://gusec.edu.in/contact/ | M24: https://gusec.edu.in/contact/ | N24: A | O24: Cross-border partnerships, AI/product strategy, founder mentoring, corporate/startup collaboration. | P24: External Advisor / Mentor – AI, Product & India–Europe Market Access | Gujarat University Startup & Entrepreneurship Council (GUSEC) | Q24: Use the partnerships inbox rather than a generic startup application; propose a Germany–India ecosystem bridge plus AI/product mentoring. | R24: Functional / office email | S24: 46291 | T24: Already contacted | V24: Already emailed in earlier batch (same address)
A25: 24 | B25: Gujarat | C25: Ahmedabad | D25: Accelerator / Incubator | E25: i-Hub Gujarat | F25: Government of Gujarat Innovation Hub | G25: Hiranmay Mahanta | H25: CEO | I25: ceo@ihubgujarat.in | J25: partnership@ihubgujarat.in | K25: +91 9825013774 | L25: https://ihubgujarat.in/our-team | M25: https://ihubgujarat.in/our-team | N25: A | O25: Startup mentoring, product/GTM, AI adoption, enterprise connects, international ecosystem access. | P25: External Advisor / Mentor – AI, Product & India–Europe Startup Ecosystem | Government of Gujarat Innovation Hub | Q25: Write directly to the named contact or functional incubation inbox; offer specific advisor/mentor contribution rather than asking for a job. | R25: Named contact + email | S25: 46291 | T25: Sent | U25: 46291 | V25: Additional high-value target
A26: 25 | B26: Gujarat | C26: Ahmedabad | D26: B-School | E26: IIM Ahmedabad | F26: IIMA Ventures (formerly CIIE.CO) | G26: IIMA Ventures Team | H26: Venture support team | I26: ciie@iima.ac.in | K26: +91 79 7152 4835 | L26: https://www.indiascienceandtechnology.gov.in/organisationscentresofexcelle/centre-innovation-incubation-entrepreneurship-ciie | M26: https://www.indiascienceandtechnology.gov.in/organisationscentresofexcelle/centre-innovation-incubation-entrepreneurship-ciie | N26: A | O26: Corporate innovation, enterprise GTM, AI/platform strategy, founder coaching, Europe access. | P26: External Advisor / Mentor – AI, Product & India–Europe Market Access | IIMA Ventures (formerly CIIE.CO) | Q26: Approach with a senior external-advisor proposition focused on enterprise tech, AI and cross-border market access. | R26: Functional / office email | S26: 46291 | T26: Skipped | V26: Already emailed IIMA Ventures
A27: 26 | B27: Gujarat | C27: Gandhinagar | D27: Engineering / Technology University | E27: Pandit Deendayal Energy University (PDEU) | F27: PDEU Innovation & Incubation Centre | G27: Abhinav Kapadia | H27: CEO / Director | I27: iic@pdpu.ac.in | K27: +91 79 23275143 / 44; +91 97265 00903 | L27: https://iic.pdeu.ac.in/about/ | M27: https://iic.pdeu.ac.in/about/ | N27: A | O27: AI/digital transformation, enterprise innovation, startup scaling, corporate partnerships. | P27: External Advisor / Mentor – AI, Product & India–Europe Market Access | PDEU Innovation & Incubation Centre | Q27: Address the CEO/Director via the centre email and request external advisor/mentor empanelment. | R27: Named contact + email | S27: 46291 | T27: Already contacted | V27: Already emailed in earlier batch (same address)
A28: 27 | B28: Gujarat | C28: Gandhinagar | D28: State / UT Government Startup Mission | E28: Industries Commissionerate, Government of Gujarat | F28: Startup Gujarat Cell | G28: Startup Gujarat Cell | H28: State startup nodal agency | I28: icstup@gujarat.gov.in | J28: startupgujaratcell@gmail.com | K28: 079-23252588 | L28: https://www.startupindia.gov.in/content/sih/en/state-startup-policies/Gujarat-state-policy.html | M28: https://www.startupindia.gov.in/content/sih/en/state-startup-policies/Gujarat-state-policy.html | N28: A | O28: Mentor/advisor contribution to state startup programs, founder capacity building, AI adoption, international ecosystem connections. | P28: External Advisor / Mentor Support for Startup Gujarat Cell | Q28: Email the state startup / innovation team with a concise advisor profile and offer specific mentor contributions. | R28: Functional / office email | S28: 46291 | T28: Sent | U28: 46291 | V28: Government / state ecosystem target
A29: 28 | B29: Haryana | C29: Sonipat | D29: Accelerator / Incubator | E29: Ashoka University | F29: InfoEdge Centre for Entrepreneurship | G29: Priyank Narayan | H29: Founding Director | I29: entrepreneurship@ashoka.edu.in | L29: https://www.ashoka.edu.in/page/cfe/ | M29: https://www.ashoka.edu.in/page/cfe/ | N29: A | O29: Entrepreneurship education, AI/product strategy, founder mentoring, India–Europe ecosystem access. | P29: External Advisor / Mentor – AI, Product & India–Europe Market Access | InfoEdge Centre for Entrepreneurship | Q29: Write to the centre referencing the Founding Director and offer mentoring, venture reviews and international ecosystem connections. | R29: Named contact + email | S29: 46291 | T29: Sent | U29: 46291
A30: 29 | B30: Haryana | C30: Mahendragarh | D30: Accelerator / Incubator | E30: Central University of Haryana | F30: Centre for Innovation & Incubation | G30: Centre for Innovation & Incubation | H30: Centre office | I30: ssunita@cuh.ac.in | K30: +91 1285 260225 | L30: https://www.cuh.ac.in/ciifcl.aspx | M30: https://www.cuh.ac.in/ciifcl.aspx | N30: B | O30: Digital platforms, AI/data, business models, venture readiness, mentoring. | P30: External Advisor / Mentor – AI, Product & India–Europe Market Access | Centre for Innovation & Incubation | Q30: Email the centre with an external mentor/advisor proposal and offer structured monthly startup clinics. | R30: Functional / office email | S30: 46291 | T30: Sent | U30: 46291
A31: 30 | B31: Haryana | C31: Rohtak | D31: B-School | E31: IIM Rohtak | F31: Entrepreneurship Cell / Bizdome | G31: Entrepreneurship Cell Team | H31: E-Cell / Bizdome | I31: ecell@iimrohtak.ac.in | L31: https://iimrohtak.ac.in/students-clubs-and-committees.php | M31: https://iimrohtak.ac.in/students-clubs-and-committees.php | N31: A | O31: Founder mentoring, business model/GTM, enterprise readiness, AI adoption, India–Europe market access. | P31: External Advisor / Mentor – AI, Product & India–Europe Startup Ecosystem | Entrepreneurship Cell / Bizdome | Q31: Write directly to the named contact or functional incubation inbox; offer specific advisor/mentor contribution rather than asking for a job. | R31: Functional / office email | S31: 46291 | T31: Sent | U31: 46291 | V31: Additional high-value target
A32: 31 | B32: Haryana | C32: Chandigarh | D32: State / UT Government Startup Mission | E32: Startup Haryana – Industries & Commerce Department | F32: Startup Haryana Cell | G32: Rahul Bamel | H32: Deputy Director | I32: startupharyanacell@gmail.com | K32: +91 172-467-1337 | L32: https://startupharyana.gov.in/front/whos-n-who | M32: https://startupharyana.gov.in/front/whos-n-who | N32: A | O32: Mentor/advisor contribution to state startup programs, founder capacity building, AI adoption, international ecosystem connections. | P32: External Advisor / Mentor Support for Startup Haryana Cell | Q32: Email the state startup / innovation team with a concise advisor profile and offer specific mentor contributions. | R32: Named contact + email | S32: 46291 | T32: Sent | U32: 46291 | V32: Government / state ecosystem target
A33: 32 | B33: Himachal Pradesh | C33: Mandi | D33: Engineering / Technology University | E33: IIT Mandi | F33: IIT Mandi Catalyst | G33: Anil Singh | H33: General Manager | I33: gm@iitmandicatalyst.in | L33: https://iitmandi.ac.in/directory | M33: https://iitmandi.ac.in/directory | N33: A | O33: AI/cloud/platform engineering, deep-tech commercialization, enterprise GTM, founder mentoring. | P33: External Advisor / Mentor – AI, Product & India–Europe Market Access | IIT Mandi Catalyst | Q33: Write to the GM; optionally copy Faculty In-Charge Prof. Dipankar Deb (dipankar@iitmandi.ac.in). | R33: Named contact + email | S33: 46291 | T33: Sent | U33: 46291
A34: 33 | B34: Himachal Pradesh | C34: Shimla | D34: State / UT Government Startup Mission | E34: Startup Himachal – Department of Industries | F34: Startup Himachal Cell | G34: Startup Himachal Cell Team | H34: State startup nodal agency | I34: startuphimachal@gmail.com | K34: 0177-2659735 | L34: https://www.startupindia.gov.in/content/sih/en/state-startup-policies/Himachal-Pradesh-state-policy.html | M34: https://www.startupindia.gov.in/content/sih/en/state-startup-policies/Himachal-Pradesh-state-policy.html | N34: B | O34: Mentor/advisor contribution to state startup programs, founder capacity building, AI adoption, international ecosystem connections. | P34: External Advisor / Mentor Support for Startup Himachal Cell | Q34: Email the state startup / innovation team with a concise advisor profile and offer specific mentor contributions. | R34: Functional / office email | S34: 46291 | T34: Sent | U34: 46291 | V34: Government / state ecosystem target
A35: 34 | B35: Jammu & Kashmir | C35: Jammu | D35: Accelerator / Incubator | E35: University of Jammu | F35: Business Incubation & Innovation Centre | G35: Dr. Harish Chander Dutt | H35: Coordinator | I35: helpdesk@jammuuniversity.ac.in | L35: https://jammuuniversity.ac.in/Isk/incubation-innovation-centre | M35: https://jammuuniversity.ac.in/Isk/incubation-innovation-centre | N35: C | O35: Entrepreneurship teaching, startup readiness, digital business, mentor workshops. | P35: External Advisor / Mentor – AI, Product & India–Europe Market Access | Business Incubation & Innovation Centre | Q35: Use the centre page and university helpdesk to request the Coordinator’s current direct contact before sending the advisor pitch. | R35: Named contact + email | S35: 46291 | T35: Skipped | V35: Only a general university helpdesk email
A36: 35 | B36: Jammu & Kashmir | C36: Srinagar | D36: Accelerator / Incubator | E36: University of Kashmir | F36: Centre for Innovation, Incubation & Entrepreneurship (CIIE) | G36: Dr. Bilal Ahmad Malik | H36: Coordinator | I36: bilalmalik@kashmiruniversity.ac.in | J36: ciie@uok.edu.in | K36: +91 91495 11050 | L36: https://ciie.uok.edu.in/Main/ContactUs.aspx | M36: https://ciie.uok.edu.in/Main/ContactUs.aspx | N36: A | O36: Entrepreneurship mentoring, digital transformation, commercialization, market connections. | P36: External Advisor / Mentor – AI, Product & India–Europe Market Access | Centre for Innovation, Incubation & Entrepreneurship (CIIE) | Q36: Email the Coordinator with specific offerings: venture review, AI/product strategy, Europe market access. | R36: Named contact + email | S36: 46291 | T36: Sent | U36: 46291
A37: 36 | B37: Jammu & Kashmir | C37: Jammu | D37: B-School | E37: IIM Jammu | F37: Foundation for Entrepreneurship Innovation & Skill Development / CIED | G37: Kannav Padha | H37: Incubation Manager | I37: manager.itbi@iimj.ac.in | L37: https://www.iimj.ac.in/directory.php | M37: https://www.iimj.ac.in/directory.php | N37: A | O37: Product/GTM, corporate innovation, founder coaching, AI adoption, India–Europe networks. | P37: External Advisor / Mentor – AI, Product & India–Europe Market Access | Foundation for Entrepreneurship Innovation & Skill Development / CIED | Q37: Write directly to the Incubation Manager; offer a 6–12 month advisor/mentor-in-residence engagement. | R37: Named contact + email | S37: 46291 | T37: Sent | U37: 46291
A38: 37 | B38: Jammu & Kashmir | C38: Awantipora | D38: Engineering / Technology University | E38: Islamic University of Science & Technology (IUST) | F38: Centre for Innovation & Entrepreneurship Development (CIED) | G38: CIED IUST Team | H38: Incubation office | I38: cied@iust.ac.in | K38: +91 1933 453396 | L38: https://www.ciediust.in/ | M38: https://www.ciediust.in/ | N38: B | O38: AI/digital ventures, product strategy, startup execution, entrepreneurship mentoring. | P38: External Advisor / Mentor – AI, Product & India–Europe Market Access | Centre for Innovation & Entrepreneurship Development (CIED) | Q38: Request external advisor/mentor association, offering AI/product strategy and founder office hours. | R38: Functional / office email | S38: 46291 | T38: Sent | U38: 46291
A39: 38 | B39: Jammu & Kashmir | C39: Srinagar | D39: Engineering / Technology University | E39: NIT Srinagar | F39: Innovation, Incubation & Entrepreneurship Development Centre (IIEDC) | G39: Prof. Babar Ahmad | H39: Head, IIEDC | I39: babar@nitsri.ac.in | J39: iiedc@nitsri.ac.in | K39: +91 97977 57234 | L39: https://nitsri.ac.in/Pages/CentreList.aspx | M39: https://nitsri.ac.in/Pages/CentreList.aspx | N39: A | O39: Technology entrepreneurship, AI/product architecture, venture reviews, industry connections. | P39: External Advisor / Mentor – AI, Product & India–Europe Market Access | Innovation, Incubation & Entrepreneurship Development Centre (IIEDC) | Q39: Write to the Head asking to join the centre’s external mentor/advisor network. | R39: Named contact + email | S39: 46291 | T39: Sent | U39: 46291
A40: 39 | B40: Jammu & Kashmir | C40: Pampore | D40: State / UT Government Startup Mission | E40: Jammu & Kashmir Entrepreneurship Development Institute (JKEDI) | F40: J&K Startup Mission | G40: JKEDI Startup / Incubation Team | H40: State/UT startup nodal agency | I40: jkediciibm@gmail.com | K40: 7006504038 | L40: https://www.startupindia.gov.in/content/sih/en/state-startup-policies/Jammu-and-Kashmir-state-policy.html | M40: https://www.startupindia.gov.in/content/sih/en/state-startup-policies/Jammu-and-Kashmir-state-policy.html | N40: A | O40: Mentor/advisor contribution to state startup programs, founder capacity building, AI adoption, international ecosystem connections. | P40: External Advisor / Mentor Support for J&K Startup Mission | Q40: Email the state startup / innovation team with a concise advisor profile and offer specific mentor contributions. | R40: Functional / office email | S40: 46291 | T40: Sent | U40: 46291 | V40: Government / state ecosystem target
...

Sheet Engineering
A1: State / UT | B1: City | C1: Institution / Organisation | D1: Incubator / Program / Unit | E1: Contact Name | F1: Contact Role | G1: Primary Email | H1: CC / Alternate Email | I1: Phone | J1: Contact / Profile URL | K1: Official Source URL | L1: Priority | M1: Suggested Subject | N1: Best Entry Route | O1: Contact Quality | P1: Email Status | Q1: Notes
A2: Andhra Pradesh | B2: Sri City | C2: IIIT Sri City | D2: Gyan Circle Ventures | E2: Gyan Circle Ventures Team | F2: Incubation team | G2: gcv.manager@iiits.in | J2: https://msh.meity.gov.in/tide/incubatorslist | K2: https://msh.meity.gov.in/tide/incubatorslist | L2: A | M2: External Advisor / Mentor – AI, Product & India–Europe Market Access | Gyan Circle Ventures | N2: Email the incubation manager with a focused AI/platform + cross-border advisory proposition. | O2: Functional / office email | P2: Not Contacted
A3: Arunachal Pradesh | B3: Nirjuli | C3: NERIST | D3: Incubation & Entrepreneurship Cell (IEC) | E3: Prof. Ningrinla Marchang | F3: Coordinator, Incubation & Entrepreneurship Cell | G3: nm@nerist.ac.in | J3: https://nerist.ac.in/facilities/sric/incubation-entrepreneurship/ | K3: https://nerist.ac.in/facilities/sric/incubation-entrepreneurship/ | L3: B | M3: External Advisor / Mentor – AI, Product & India–Europe Market Access | Incubation & Entrepreneurship Cell (IEC) | N3: Write directly to the Coordinator requesting empanelment as an external advisor/mentor. | O3: Named contact + email | P3: Not Contacted
A4: Assam | B4: Guwahati | C4: IIT Guwahati | D4: Technology Incubation Centre (TIC) | E4: TIC Team | F4: Incubation office | G4: tic@iitg.ac.in | I4: +91 361 2583194 / 2583191 | J4: https://iitgtic.com/index_contacts | K4: https://iitgtic.com/index_contacts | L4: A | M4: External Advisor / Mentor – AI, Product & India–Europe Market Access | Technology Incubation Centre (TIC) | N4: Email TIC with an advisor profile and areas: AI, cloud, enterprise SaaS, Europe market access. | O4: Functional / office email | P4: Not Contacted
A5: Bihar | B5: Patna | C5: IIT Patna | D5: Incubation Centre IIT Patna | E5: Mr. Gopi Krishna Sakhinala | F5: Incubation contact | G5: iciitp@iitp.ac.in | I5: +91 79709 72747 | J5: https://iciitp.com/index.php/contact/ | K5: https://iciitp.com/index.php/contact/ | L5: A | M5: External Advisor / Mentor – AI, Product & India–Europe Market Access | Incubation Centre IIT Patna | N5: Email the centre and reference interest in external advisor / startup review panel roles. | O5: Named contact + email | P5: Not Contacted
A6: Bihar | B6: Patna | C6: NIT Patna | D6: Incubation Center NIT Patna | E6: Incubation Center Team | F6: Incubation office | G6: Incubation@nitp.ac.in | J6: https://incubationcenter.nitp.ac.in/ | K6: https://incubationcenter.nitp.ac.in/ | L6: B | M6: External Advisor / Mentor – AI, Product & India–Europe Market Access | Incubation Center NIT Patna | N6: Request an external mentor/advisor association and offer AI/product/GTM sessions for incubatees. | O6: Functional / office email | P6: Not Contacted
A7: Chhattisgarh | B7: Naya Raipur | C7: IIIT Naya Raipur | D7: Foundation for Technology & Business Incubation / Entrepreneurship | E7: Dr. Amit Agarwal | F7: Incubation contact | G7: amitag@iiitnr.edu.in | I7: +91 89541 67407 | J7: https://www.invest.cg.gov.in/startup | K7: https://www.invest.cg.gov.in/startup | L7: B | M7: External Advisor / Mentor – AI, Product & India–Europe Market Access | Foundation for Technology & Business Incubation / Entrepreneurship | N7: Write to Dr. Agarwal requesting consideration for external advisor/mentor pool. | O7: Named contact + email | P7: Not Contacted
A8: Chhattisgarh | B8: Bhilai | C8: IIT Bhilai | D8: IIT Bhilai Innovation & Technology Foundation (IBITF) | E8: Prof. Souradyuti Paul | F8: Incubation / innovation contact | G8: tih@iitbhilai.ac.in | I8: +91 99710 02706 | J8: https://www.invest.cg.gov.in/startup | K8: https://www.invest.cg.gov.in/startup | L8: A | M8: External Advisor / Mentor – AI, Product & India–Europe Market Access | IIT Bhilai Innovation & Technology Foundation (IBITF) | N8: Contact the innovation foundation and propose external advisory support for AI/digital ventures. | O8: Named contact + email | P8: Not Contacted
A9: Chhattisgarh | B9: Raipur | C9: NIT Raipur | D9: NIT Raipur Foundation for Innovation & Entrepreneurship (NITRRFIE) | E9: Medha Singh | F9: Incubation contact | G9: nitrrfie@nitrr.ac.in | I9: +91 94062 02248 | J9: https://www.invest.cg.gov.in/startup | K9: https://www.invest.cg.gov.in/startup | L9: B | M9: External Advisor / Mentor – AI, Product & India–Europe Market Access | NIT Raipur Foundation for Innovation & Entrepreneurship (NITRRFIE) | N9: Email the named contact with advisor CV and proposed monthly founder office hours. | O9: Named contact + email | P9: Not Contacted
A10: Delhi | B10: New Delhi | C10: IIIT Delhi | D10: IIIT Delhi Innovation & Incubation Center (IIITD-IC) | E10: IIITD Innovation & Incubation Center | F10: Incubation office | G10: info@iiitdic.in | J10: https://msh.meity.gov.in/tide/incubatorslist | K10: https://msh.meity.gov.in/tide/incubatorslist | L10: A | M10: External Advisor / Mentor – AI, Product & India–Europe Market Access | IIIT Delhi Innovation & Incubation Center (IIITD-IC) | N10: Email with a proposal to join the mentor/advisor network for AI/software ventures. | O10: Functional / office email | P10: Not Contacted
A11: Delhi | B11: New Delhi | C11: IIT Delhi | D11: FITT – Foundation for Innovation and Technology Transfer | E11: Dr. Ashutosh Pastor | F11: Vice President – Incubation | G11: AshutoshPastor@fitt-iitd.in | J11: https://fitt-iitd.in/web/fittteam | K11: https://fitt-iitd.in/web/fittteam | L11: A | M11: External Advisor / Mentor – AI, Product & India–Europe Market Access | FITT | N11: Write directly to VP Incubation; attach concise advisor bio and specify AI/cloud, enterprise GTM and India–Europe bridge. | O11: Named contact + email | P11: Not Contacted
A12: Delhi | B12: New Delhi | C12: Netaji Subhas University of Technology (NSUT) | D12: NSUT Incubation & Innovation Foundation | E12: NSUT-IIF Team | F12: Incubation foundation | G12: nsutiif@nsut.ac.in | H12: connect.nsutiif@nsut.ac.in | I12: +91 9205475058 | J12: https://nsutiif.in/contact | K12: https://nsutiif.in/contact | L12: A | M12: External Advisor / Mentor – AI, Product & India–Europe Startup Ecosystem | NSUT Incubation & Innovation Foundation | N12: Write directly to the named contact or functional incubation inbox; offer specific advisor/mentor contribution rather than asking for a job. | O12: Functional / office email | P12: Not Contacted | Q12: Additional high-value target
A13: Goa | B13: Zuarinagar | C13: BITS Pilani – Goa Campus | D13: CIIE / BGIIES | E13: Prof. Saroj Sundar Baral | F13: Faculty-in-Charge, CIIE | G13: ssbaral@goa.bits-pilani.ac.in | I13: +91 832 2580119 | J13: https://www.bits-pilani.ac.in/goa/ciie/ | K13: https://www.bits-pilani.ac.in/goa/ciie/ | L13: A | M13: External Advisor / Mentor – AI, Product & India–Europe Market Access | CIIE / BGIIES | N13: Write to the Faculty-in-Charge proposing advisory sessions, venture reviews and India–Europe startup connects. | O13: Named contact + email | P13: Not Contacted
A14: Gujarat | B14: Gandhinagar | C14: Pandit Deendayal Energy University (PDEU) | D14: PDEU Innovation & Incubation Centre | E14: Abhinav Kapadia | F14: CEO / Director | G14: iic@pdpu.ac.in | I14: +91 79 23275143 / 44; +91 97265 00903 | J14: https://iic.pdeu.ac.in/about/ | K14: https://iic.pdeu.ac.in/about/ | L14: A | M14: External Advisor / Mentor – AI, Product & India–Europe Market Access | PDEU Innovation & Incubation Centre | N14: Address the CEO/Director via the centre email and request external advisor/mentor empanelment. | O14: Named contact + email | P14: Not Contacted
A15: Himachal Pradesh | B15: Mandi | C15: IIT Mandi | D15: IIT Mandi Catalyst | E15: Anil Singh | F15: General Manager | G15: gm@iitmandicatalyst.in | J15: https://iitmandi.ac.in/directory | K15: https://iitmandi.ac.in/directory | L15: A | M15: External Advisor / Mentor – AI, Product & India–Europe Market Access | IIT Mandi Catalyst | N15: Write to the GM; optionally copy Faculty In-Charge Prof. Dipankar Deb (dipankar@iitmandi.ac.in). | O15: Named contact + email | P15: Not Contacted
A16: Jammu & Kashmir | B16: Awantipora | C16: Islamic University of Science & Technology (IUST) | D16: Centre for Innovation & Entrepreneurship Development (CIED) | E16: CIED IUST Team | F16: Incubation office | G16: cied@iust.ac.in | I16: +91 1933 453396 | J16: https://www.ciediust.in/ | K16: https://www.ciediust.in/ | L16: B | M16: External Advisor / Mentor – AI, Product & India–Europe Market Access | Centre for Innovation & Entrepreneurship Development (CIED) | N16: Request external advisor/mentor association, offering AI/product strategy and founder office hours. | O16: Functional / office email | P16: Not Contacted
A17: Jammu & Kashmir | B17: Srinagar | C17: NIT Srinagar | D17: Innovation, Incubation & Entrepreneurship Development Centre (IIEDC) | E17: Prof. Babar Ahmad | F17: Head, IIEDC | G17: babar@nitsri.ac.in | H17: iiedc@nitsri.ac.in | I17: +91 97977 57234 | J17: https://nitsri.ac.in/Pages/CentreList.aspx | K17: https://nitsri.ac.in/Pages/CentreList.aspx | L17: A | M17: External Advisor / Mentor – AI, Product & India–Europe Market Access | Innovation, Incubation & Entrepreneurship Development Centre (IIEDC) | N17: Write to the Head asking to join the centre’s external mentor/advisor network. | O17: Named contact + email | P17: Not Contacted
A18: Jharkhand | B18: Dhanbad | C18: IIT (ISM) Dhanbad | D18: Centre for Innovation, Incubation & Entrepreneurship (CIIE) | E18: CIIE IIT (ISM) Team | F18: Incubation office | G18: ciie@iitism.ac.in | I18: +91 326 2235870 | J18: https://ciie.iitism.ac.in/incubation.php | K18: https://ciie.iitism.ac.in/incubation.php | L18: A | M18: External Advisor / Mentor – AI, Product & India–Europe Market Access | Centre for Innovation, Incubation & Entrepreneurship (CIIE) | N18: Email CIIE with a tailored external advisor proposition for technology and enterprise ventures. | O18: Functional / office email | P18: Not Contacted
A19: Karnataka | B19: Bengaluru | C19: IIIT Bangalore | D19: IIIT-B Innovation Centre | E19: Innovation Centre Team | F19: Incubation office | G19: ceoinnovationcenter@iiitb.ac.in | I19: +91 80 41407777 | J19: https://ic.iiitb.ac.in/ | K19: https://ic.iiitb.ac.in/ | L19: A | M19: External Advisor / Mentor – AI, Product & India–Europe Market Access | IIIT-B Innovation Centre | N19: Write to the Innovation Centre CEO inbox requesting advisor/mentor panel consideration. | O19: Functional / office email | P19: Not Contacted
A20: Karnataka | B20: Manipal | C20: Manipal Academy of Higher Education | D20: Manipal University Technology Business Incubator (MUTBI) | E20: MUTBI Team | F20: Incubation office | G20: mutbi.mit@manipal.edu | I20: +91 820 2925051 | J20: https://www.manipal.edu/mu/important-links/innovation-entrepreneruship/mutbi.html | K20: https://www.manipal.edu/mu/important-links/innovation-entrepreneruship/mutbi.html | L20: A | M20: External Advisor / Mentor – AI, Product & India–Europe Market Access | Manipal University Technology Business Incubator (MUTBI) | N20: Email MUTBI seeking empanelment as an external technology/business advisor. | O20: Functional / office email | P20: Not Contacted
A21: Karnataka | B21: Surathkal | C21: NITK Surathkal | D21: Science & Technology Entrepreneurs’ Park (STEP) | E21: Dr. Subray R. Hegde | F21: Director In-Charge | G21: step@nitk.edu.in | I21: +91 87625 88011 | J21: https://step.nitk.ac.in/about.html | K21: https://step.nitk.ac.in/about.html | L21: A | M21: External Advisor / Mentor – AI, Product & India–Europe Market Access | Science & Technology Entrepreneurs’ Park (STEP) | N21: Write to Director In-Charge proposing startup reviews, AI/product mentoring and corporate-market linkage. | O21: Named contact + email | P21: Not Contacted
A22: Kerala | B22: Kollam / Coimbatore / Bengaluru | C22: Amrita Vishwa Vidyapeetham | D22: Amrita Technology Business Incubator (Amrita TBI) | E22: Amrita TBI Team | F22: Incubation office | G22: info@amritatbi.com | I22: +91 476 2805450; +91 70259 00047 | J22: https://www.amritatbi.com/incubation-apply.html | K22: https://www.amritatbi.com/incubation-apply.html | L22: A | M22: External Advisor / Mentor – AI, Product & India–Europe Market Access | Amrita Technology Business Incubator (Amrita TBI) | N22: Email with an advisor proposal covering AI/cloud, commercialization, founder mentoring and Europe market access. | O22: Functional / office email | P22: Not Contacted
A23: Kerala | B23: Kochi | C23: Cochin University of Science and Technology (CUSAT) | D23: CUSAT Technology Business Incubator | E23: Dr. Kailasnath M. | F23: Co-ordinator | G23: cusatechfoundation@cusat.ac.in | H23: tbi@cusat.ac.in | I23: +91 98950 25773 / 98950 14481 | J23: https://tbi.cusat.ac.in/ | K23: https://tbi.cusat.ac.in/ | L23: A | M23: External Advisor / Mentor – AI, Product & India–Europe Market Access | CUSAT Technology Business Incubator | N23: Write directly to the Co-ordinator with a one-page external advisor profile. | O23: Named contact + email | P23: Not Contacted
A24: Kerala | B24: Kochi | C24: IIITM-K / Kerala Digital University ecosystem | D24: Maker Village | E24: Maker Village Team | F24: Incubation office | G24: makervillage@iiitmk.ac.in | I24: +91 484 2976688 | J24: https://makervillage.in/contactus.php | K24: https://makervillage.in/contactus.php | L24: B | M24: External Advisor / Mentor – AI, Product & India–Europe Market Access | Maker Village | N24: Offer digital/AI/platform commercialization and enterprise partnership advice, complementing hardware expertise. | O24: Functional / office email | P24: Not Contacted
A25: Kerala | B25: Kozhikode | C25: NIT Calicut | D25: Technology Business Incubator (TBI) | E25: TBI NIT Calicut | F25: Incubation office | G25: tbi@nitc.ac.in | I25: +91 495 2286147 | J25: https://my.msme.gov.in/inc/HIList.aspx | K25: https://my.msme.gov.in/inc/HIList.aspx | L25: B | M25: External Advisor / Mentor – AI, Product & India–Europe Market Access | Technology Business Incubator (TBI) | N25: Email the TBI and request the current CEO/Coordinator for an external advisor discussion. | O25: Named contact + email | P25: Not Contacted
A26: Maharashtra | B26: Pune | C26: COEP Technological University | D26: Bhau Institute of Innovation, Entrepreneurship & Leadership | E26: Bhau Institute Team | F26: Incubation team | G26: manager.bhau@coeptech.ac.in | I26: +91 20 25507023 | J26: https://bhau.org/contact/ | K26: https://bhau.org/contact/ | L26: A | M26: External Advisor / Mentor – AI, Product & India–Europe Market Access | Bhau Institute of Innovation, Entrepreneurship & Leadership | N26: Email the manager with a targeted advisor proposition and offer founder office hours / pitch reviews. | O26: Functional / office email | P26: Not Contacted
A27: Maharashtra | B27: Mumbai | C27: IIT Bombay | D27: Society for Innovation and Entrepreneurship (SINE) | E27: SINE Team | F27: Partnership / incubation team | G27: sine@sineiitb.org | I27: +91 22 2576 7016 | J27: https://sineiitb.org/contact | K27: https://sineiitb.org/contact | L27: A | M27: External Advisor / Mentor – AI, Product & India–Europe Market Access | Society for Innovation and Entrepreneurship (SINE) | N27: Use SINE contact route with query category “For Partnership”; position as External Advisor/Mentor, not applicant. | O27: Functional / office email | P27: Not Contacted
A28: Maharashtra | B28: Pune | C28: Savitribai Phule Pune University | D28: Science and Technology Park | E28: Science & Technology Park Team | F28: Innovation / incubation office | G28: stp@scitechpark.org.in | I28: +91 20 25699206; +91 99600 00963 | J28: https://scitechpark.org.in/contact-us/ | K28: https://scitechpark.org.in/contact-us/ | L28: A | M28: External Advisor / Mentor – AI, Product & India–Europe Market Access | Science and Technology Park | N28: Approach as a technology commercialization and market-access advisor, with AI/cloud and corporate-network focus. | O28: Functional / office email | P28: Not Contacted
A29: Odisha | B29: Bhubaneswar | C29: IIT Bhubaneswar | D29: Research & Entrepreneurship Park (REP) | E29: REP Team | F29: Research / incubation office | G29: office.rep@iitbbs.ac.in | I29: +91 74400 12530 | J29: https://rep.iitbbs.ac.in/contact/ | K29: https://rep.iitbbs.ac.in/contact/ | L29: A | M29: External Advisor / Mentor – AI, Product & India–Europe Market Access | Research & Entrepreneurship Park (REP) | N29: Email REP to propose advisory support for research commercialization and technology startups. | O29: Functional / office email | P29: Not Contacted
A30: Odisha | B30: Bhubaneswar | C30: KIIT | D30: KIIT Technology Business Incubator (KIIT-TBI) | E30: Dr. Namrata Misra | F30: Incubation contact | G30: namrata@kiitincubator.in | H30: tbi@kiitincubator.in | I30: +91 82494 71927; +91 82490 28648 | J30: https://kiitincubator.in/contact-us/ | K30: https://kiitincubator.in/contact-us/ | L30: A | M30: External Advisor / Mentor – AI, Product & India–Europe Market Access | KIIT Technology Business Incubator (KIIT-TBI) | N30: Write to the named contact and TBI inbox requesting External Advisor / Mentor panel consideration. | O30: Named contact + email | P30: Not Contacted
A31: Odisha | B31: Rourkela | C31: NIT Rourkela | D31: Foundation for Technology & Business Incubation (FTBI) | E31: Chiranjibi Samal | F31: CEO / FTBI leadership | G31: samalc-ftbi@nitrkl.ac.in | H31: ftbi@nitrkl.ac.in | I31: +91 661 2462230 / 2231 | J31: https://www.ftbi-nitrkl.org/team-ftbi | K31: https://www.ftbi-nitrkl.org/team-ftbi | L31: A | M31: External Advisor / Mentor – AI, Product & India–Europe Market Access | Foundation for Technology & Business Incubation (FTBI) | N31: Write directly to FTBI leadership proposing AI/product, enterprise GTM and startup governance mentoring. | O31: Named contact + email | P31: Not Contacted
A32: Punjab | B32: Rupnagar | C32: IIT Ropar | D32: iHub – AWaDH | E32: AWaDH Partnerships Team | F32: Partnerships / startups | G32: partnerships@ihub-awadh.in | H32: startups@ihub-awadh.in; contact.awadh@iitrpr.ac.in | I32: +91 1881 232601 | J32: https://ihub-awadh.in/contact-us/ | K32: https://ihub-awadh.in/contact-us/ | L32: A | M32: External Advisor / Mentor – AI, Product & India–Europe Market Access | iHub | N32: Lead with the partnerships email; propose cross-border enterprise connections plus AI/platform commercialization. | O32: Functional / office email | P32: Not Contacted
A33: Punjab | B33: Patiala | C33: Thapar Institute of Engineering & Technology | D33: Entrepreneurship Development Cell (EDC) | E33: Dr. M.D. Singh | F33: President, EDC | G33: edc@thapar.edu | H33: mdsingh@thapar.edu | J33: https://www.thapar.edu/students/pages/edc | K33: https://www.thapar.edu/students/pages/edc | L33: A | M33: External Advisor / Mentor – AI, Product & India–Europe Startup Ecosystem | Entrepreneurship Development Cell (EDC) | N33: Write directly to the named contact or functional incubation inbox; offer specific advisor/mentor contribution rather than asking for a job. | O33: Named contact + email | P33: Not Contacted | Q33: Additional high-value target
A34: Rajasthan | B34: Jodhpur | C34: IIT Jodhpur | D34: Technology Innovation & Startup Centre (TISC) | E34: TISC Team | F34: Incubation office | G34: ceo@tisc.iitj.ac.in | I34: +91 291 2802226 | J34: https://www.iitj.ac.in/tisc/en/contact | K34: https://www.iitj.ac.in/tisc/en/contact | L34: A | M34: External Advisor / Mentor – AI, Product & India–Europe Market Access | Technology Innovation & Startup Centre (TISC) | N34: Write to the CEO inbox requesting advisor/mentor panel consideration and offer founder office hours. | O34: Functional / office email | P34: Not Contacted
A35: Rajasthan | B35: Jaipur | C35: MNIT Jaipur | D35: MNIT Innovation & Incubation Centre (MIIC) | E35: MIIC Team | F35: Incubation office | G35: miic@mnit.ac.in | I35: +91 98281 99938 | J35: https://miic.mnit.ac.in/resource/networking-and-collaboration | K35: https://miic.mnit.ac.in/resource/networking-and-collaboration | L35: A | M35: External Advisor / Mentor – AI, Product & India–Europe Market Access | MNIT Innovation & Incubation Centre (MIIC) | N35: Email MIIC with a direct external-advisor proposal focused on AI/product strategy and market access. | O35: Functional / office email | P35: Not Contacted
A36: Sikkim | B36: Majitar | C36: Sikkim Manipal Institute of Technology | D36: AIC-SMUTBI | E36: Dr. Tej Chingtham | F36: CEO | G36: ceo@smutbi.com | H36: contact@smutbi.com | I36: +91 359 2246622 | J36: https://www.smutbi.com/contact-us/ | K36: https://www.smutbi.com/contact-us/ | L36: A | M36: External Advisor / Mentor – AI, Product & India–Europe Market Access | AIC-SMUTBI | N36: Write to the CEO and copy general contact; offer external advisor support for technology commercialization and scaling. | O36: Named contact + email | P36: Not Contacted
A37: Tamil Nadu | B37: Chennai | C37: IIT Madras | D37: IIT Madras Incubation Cell | E37: IITM Incubation Cell Team | F37: Incubation office | G37: jaya@incubation.iitm.ac.in | J37: https://msh.meity.gov.in/tide/incubatorslist | K37: https://msh.meity.gov.in/tide/incubatorslist | L37: A | M37: External Advisor / Mentor – AI, Product & India–Europe Market Access | IIT Madras Incubation Cell | N37: Send a senior advisor proposition around enterprise tech, AI/cloud and India–Europe market access; mention mentoring/teaching background. | O37: Functional / office email | P37: Not Contacted
A38: Tamil Nadu | B38: Erode | C38: Kongu Engineering College | D38: Technology Business Incubator / Innovation & Entrepreneurship Forum | E38: Dr. Praveen Kumar Subramanian | F38: Convener, Innovation & Entrepreneurship Forum | G38: praveenkumar.mts@kongu.edu | H38: iickec@kongu.edu | I38: +91 95005 75414 / +91 63826 50340 | J38: https://kongu.ac.in/kongu.ac.in/ief.php | K38: https://kongu.ac.in/kongu.ac.in/ief.php | L38: A | M38: External Advisor / Mentor – AI, Product & India–Europe Market Access | Technology Business Incubator / Innovation & Entrepreneurship Forum | N38: Write directly to the Convener; propose mentor clinics, venture reviews and AI entrepreneurship sessions. | O38: Named contact + email | P38: Not Contacted
A39: Tamil Nadu | B39: Coimbatore | C39: PSG College of Technology | D39: PSG Science & Technology Entrepreneurial Park (PSG-STEP) | E39: D. Manikandan | F39: Incubation contact | G39: step@psgtech.edu | I39: +91 422 4363300 | J39: https://nidhi.dst.gov.in/incubator/ | K39: https://nidhi.dst.gov.in/incubator/ | L39: A | M39: External Advisor / Mentor – AI, Product & India–Europe Market Access | PSG Science & Technology Entrepreneurial Park (PSG-STEP) | N39: Write to PSG-STEP with external advisor CV and focus on AI/product commercialization and corporate-market linkage. | O39: Named contact + email | P39: Not Contacted
A40: Tamil Nadu | B40: Thanjavur | C40: SASTRA Deemed University | D40: FIRST – Technology Business Incubator | E40: Nirmal Narayanan | F40: Incubation contact | G40: first@sastra.ac.in | I40: +91 86087 00551 | J40: https://nidhi.dst.gov.in/incubator/ | K40: https://nidhi.dst.gov.in/incubator/ | L40: B | M40: External Advisor / Mentor – AI, Product & India–Europe Market Access | FIRST | N40: Email FIRST with a technology/business advisor proposition; offer AI/product and enterprise scaling sessions. | O40: Named contact + email | P40: Not Contacted
...

Sheet B-Schools
A1: State / UT | B1: City | C1: Institution / Organisation | D1: Incubator / Program / Unit | E1: Contact Name | F1: Contact Role | G1: Primary Email | H1: CC / Alternate Email | I1: Phone | J1: Contact / Profile URL | K1: Official Source URL | L1: Priority | M1: Suggested Subject | N1: Best Entry Route | O1: Contact Quality | P1: Email Status | Q1: Notes
A2: Andhra Pradesh | B2: Visakhapatnam | C2: IIM Visakhapatnam | D2: FIELD – IIMV Foundation for Incubation Entrepreneurial Learning & Development | E2: FIELD Team | F2: Incubation team | G2: incubationcenter@iimv.ac.in | I2: +91 75693 09208 | J2: https://iimvfield.com/contact-us/ | K2: https://iimvfield.com/contact-us/ | L2: A | M2: External Advisor / Mentor – AI, Product & India–Europe Market Access | FIELD | N2: Email FIELD and request External Advisor / Mentor Panel consideration. | O2: Functional / office email | P2: Not Contacted
A3: Goa | B3: Sanquelim | C3: Goa Institute of Management | D3: Atal Incubation Centre – GIM Foundation (AIC-GIM) | E3: AIC-GIM Team | F3: Startup / incubation team | G3: startups@aicgim.in | I3: +91 832 2366700 | J3: https://aicgim.in/ | K3: https://aicgim.in/ | L3: A | M3: External Advisor / Mentor – AI, Product & India–Europe Market Access | Atal Incubation Centre | N3: Email the startup team requesting inclusion as an external advisor/mentor, especially for technology and scale-up cohorts. | O3: Functional / office email | P3: Not Contacted
A4: Gujarat | B4: Ahmedabad | C4: IIM Ahmedabad | D4: IIMA Ventures (formerly CIIE.CO) | E4: IIMA Ventures Team | F4: Venture support team | G4: ciie@iima.ac.in | I4: +91 79 7152 4835 | J4: https://www.indiascienceandtechnology.gov.in/organisationscentresofexcelle/centre-innovation-incubation-entrepreneurship-ciie | K4: https://www.indiascienceandtechnology.gov.in/organisationscentresofexcelle/centre-innovation-incubation-entrepreneurship-ciie | L4: A | M4: External Advisor / Mentor – AI, Product & India–Europe Market Access | IIMA Ventures (formerly CIIE.CO) | N4: Approach with a senior external-advisor proposition focused on enterprise tech, AI and cross-border market access. | O4: Functional / office email | P4: Not Contacted
